Workbook
Name gasbenchCO2template.wke: #REF!

Sheet FINAL REPORTED
A1: Run | B1: Identifier 1 | C1: Mass (mg) | D1: Amp 44 | E1: Area 44 | F1: δ13C (PDB) | G1: δ18O (SMOW)
A2: 13 | B2: 12 SPL A Path O 3A | C2: 0.208 | D2: 14281 | E2: 180.81 | F2: -0.8018214 | G2: 25.58264
A3: 14 | B3: 12 SPL A Path O 4A | C3: 0.251 | D3: 12052 | E3: 146.341 | F3: -1.1867008 | G3: 25.639263
A4: 15 | B4: 12 SPL A Path O 5A | C4: 0.249 | D4: 16673 | E4: 212.049 | F4: -1.2440825 | G4: 25.769501
A5: 16 | B5: 12 SPL A Path O 6A | C5: 0.245 | D5: 21957 | E5: 270.774 | F5: -1.0228973 | G5: 25.758695
A6: 17 | B6: 12 SPL A Path O 7A | C6: 0.233 | D6: 18377 | E6: 227.759 | F6: -0.98722819 | G6: 25.752761
A7: 18 | B7: 12 SPL A Path O 8A | C7: 0.246 | D7: 17131 | E7: 215.102 | F7: -1.1064108 | G7: 25.806074
A8: 19 | B8: 12 SPL A Path O 9A | C8: 0.213 | D8: 14001 | E8: 171 | F8: -1.1170657 | G8: 25.667999
A9: 20 | B9: 12 SPL A Path O 10A | C9: 0.248 | D9: 14981 | E9: 191.732 | F9: -0.86863515 | G9: 25.673999
A10: 21 | B10: 12 SPL A Path O 11A | C10: 0.238 | D10: 16921 | E10: 204.087 | F10: -1.1474361 | G10: 25.562873
A11: 22 | B11: 12 SPL A Path O 12A | C11: 0.2 | D11: 15359 | E11: 194.735 | F11: -0.95675149 | G11: 25.559349
A12: 25 | B12: 21 SPL A Path O 13A | C12: 0.23 | D12: 14146 | E12: 171.922 | F12: -0.83316526 | G12: 25.636084
A13: 26 | B13: 22 SPL A Path O 14A | C13: 0.212 | D13: 19518 | E13: 247.169 | F13: -0.84528089 | G13: 25.661923
... A132: 172 | B132: 12 SPL A4 Path H 113A | C132: 0.244 | D132: 12325 | E132: 155.769 | F132: -3.028011 | G132: 25.598793
B134: Standards
A136: 2 | B136: NBS 18 | C136: 0.23 | D136: 12410 | E136: 157.446 | F136: -5.0061492 | G136: 7.2640639 | I136: . | J136: δ13C (PDB) | K136: δ18O (SMOW)
A137: 3 | B137: NBS18 | C137: 0.248 | D137: 14309 | E137: 173.645 | F137: -5.0355364 | G137: 7.2168583 | I137: Ave corrected UTM all measurments | J137: =AVERAGE(F144:F174) -> 4.4594343 | K137: =AVERAGE(G144:G174) -> 26.50808
A138: 4 | B138: NBS18 | C138: 0.258 | D138: 14585 | E138: 184.826 | F138: -4.9751028 | G138: 7.161922 | I138: Std Dev | J138: =STDEV((F144:F174)) -> 0.038412005 | K138: =STDEV((G144:G174)) -> 0.054971271
A139: 5 | B139: NBS18 | C139: 0.246 | D139: 16186 | E139: 197.149 | F139: -5.0822212 | G139: 7.1540066 | I139: Known | J139: 4.49 | K139: 26.5
A140: 6 | B140: NBS 19 | C140: 0.22 | D140: 12673 | E140: 160.447 | F140: 1.976658 | G140: 28.545773
A141: 7 | B141: NBS 19 | C141: 0.286 | D141: 18792 | E141: 230.568 | F141: 2.016867 | G141: 28.601873
A142: 8 | B142: NBS 19 | C142: 0.286 | D142: 16128 | E142: 203.088 | F142: 1.9767945 | G142: 28.560183
A143: 9 | B143: NBS 19 | C143: 0.216 | D143: 10987 | E143: 139.3 | F143: 1.9949529 | G143: 28.663001
A144: 10 | B144: UTM | C144: 0.268 | D144: 14114 | E144: 171.817 | F144: 4.41547 | G144: 26.517731
A145: 11 | B145: UTM | C145: 0.224 | D145: 11107 | E145: 141.435 | F145: 4.5307531 | G145: 26.591746
A146: 12 | B146: UTM | C146: 0.22 | D146: 12045 | E146: 145.945 | F146: 4.4514845 | G146: 26.481043
A147: 23 | B147: UTM | C147: 0.242 | D147: 13358 | E147: 161.717 | F147: 4.4770123 | G147: 26.531278
A148: 24 | B148: UTM | C148: 0.25 | D148: 12838 | E148: 162.933 | F148: 4.5142618 | G148: 26.497723
A149: 35 | B149: UTM | C149: 0.274 | D149: 13732 | E149: 173.926 | F149: 4.5128529 | G149: 26.502074
A150: 36 | B150: UTM | C150: 0.296 | D150: 16472 | E150: 201.999 | F150: 4.3940418 | G150: 26.497812
A151: 47 | B151: UTM | C151: 0.242 | D151: 13205 | E151: 160.077 | F151: 4.4568831 | G151: 26.540259
... A164: 108 | B164: UTM | C164: 0.248 | D164: 13110 | E164: 160.28 | F164: 4.4053472 | G164: 26.526329
A165: 119 | B165: UTM | D165: 14087 | E165: 172.649 | F165: 4.4620745 | G165: 26.386556
A166: 120 | B166: UTM | D166: 14089 | E166: 178.972 | F166: 4.5024535 | G166: 26.521063
A167: 131 | B167: UTM | D167: 15325 | E167: 195.234 | F167: 4.4690517 | G167: 26.522579
A168: 132 | B168: UTM | D168: 18790 | E168: 230.378 | F168: 4.4542348 | G168: 26.443074
A169: 143 | B169: UTM | D169: 19128 | E169: 233.266
A170: 144 | B170: UTM | D170: 15969 | E170: 202.169 | F170: 4.4760907 | G170: 26.503312
A171: 155 | B171: UTM | D171: 16831 | E171: 215.109 | F171: 4.4685993 | G171: 26.559065
A172: 156 | B172: UTM | D172: 10807 | E172: 131.25
...

Sheet 3-Format-Final
A1: Row | B1: Identifier 1 | C1: Identifier 2 | D1: Peak Nr | E1: Ampl 44 | F1: Area 44 | G1: δ13C (PDB) | H1: δ18O (SMOW)
A3: 2 | B3: NBS 18 | C3: 0.23 | D3: 6 | E3: 13350 | F3: 169.452
A4: 6 | B4: NBS 19 | C4: 0.22 | D4: 6 | E4: 13590 | F4: 172.613
A5: 13 | B5: 12 SPL A Path O 3A | C5: 0.208 | D5: 6 | E5: 15333 | F5: 194.652
A6: 13 | B6: 12 SPL A Path O 3A | C6: 0.208 | D6: 7 | E6: 14281 | F6: 180.81 | G6: -0.8018214 | H6: 25.58264
A7: 14 | B7: 12 SPL A Path O 4A | C7: 0.251 | D7: 6 | E7: 12939 | F7: 157.223
A8: 14 | B8: 12 SPL A Path O 4A | C8: 0.251 | D8: 7 | E8: 12052 | F8: 146.341 | G8: -1.1867008 | H8: 25.639263
A9: 15 | B9: 12 SPL A Path O 5A | C9: 0.249 | D9: 6 | E9: 17843 | F9: 225.331
A10: 15 | B10: 12 SPL A Path O 5A | C10: 0.249 | D10: 7 | E10: 16673 | F10: 212.049 | G10: -1.2440825 | H10: 25.769501
A11: 16 | B11: 12 SPL A Path O 6A | C11: 0.245 | D11: 6 | E11: 23763 | F11: 288.937
A12: 16 | B12: 12 SPL A Path O 6A | C12: 0.245 | D12: 7 | E12: 21957 | F12: 270.774 | G12: -1.0228973 | H12: 25.758695
A13: 17 | B13: 12 SPL A Path O 7A | C13: 0.233 | D13: 6 | E13: 19610 | F13: 244.941
A14: 17 | B14: 12 SPL A Path O 7A | C14: 0.233 | D14: 7 | E14: 18377 | F14: 227.759 | G14: -0.98722819 | H14: 25.752761
A15: 18 | B15: 12 SPL A Path O 8A | C15: 0.246 | D15: 6 | E15: 18516 | F15: 232.02
A16: 18 | B16: 12 SPL A Path O 8A | C16: 0.246 | D16: 7 | E16: 17131 | F16: 215.102 | G16: -1.1064108 | H16: 25.806074
A17: 19 | B17: 12 SPL A Path O 9A | C17: 0.213 | D17: 6 | E17: 14870 | F17: 182.829
A18: 19 | B18: 12 SPL A Path O 9A | C18: 0.213 | D18: 7 | E18: 14001 | F18: 171 | G18: -1.1170657 | H18: 25.667999
A19: 20 | B19: 12 SPL A Path O 10A | C19: 0.248 | D19: 6 | E19: 16047 | F19: 203.691
A20: 20 | B20: 12 SPL A Path O 10A | C20: 0.248 | D20: 7 | E20: 14981 | F20: 191.732 | G20: -0.86863515 | H20: 25.673999
A21: 21 | B21: 12 SPL A Path O 11A | C21: 0.238 | D21: 6 | E21: 17997 | F21: 218.108
A22: 21 | B22: 12 SPL A Path O 11A | C22: 0.238 | D22: 7 | E22: 16921 | F22: 204.087 | G22: -1.1474361 | H22: 25.562873
A23: 22 | B23: 12 SPL A Path O 12A | C23: 0.2 | D23: 6 | E23: 16487 | F23: 209.572
A24: 22 | B24: 12 SPL A Path O 12A | C24: 0.2 | D24: 7 | E24: 15359 | F24: 194.735 | G24: -0.95675149 | H24: 25.559349
A25: 23 | B25: UTM | C25: 0.242 | D25: 6 | E25: 14249 | F25: 172.765
A26: 25 | B26: 21 SPL A Path O 13A | C26: 0.23 | D26: 6 | E26: 15228 | F26: 185.047
A27: 25 | B27: 21 SPL A Path O 13A | C27: 0.23 | D27: 7 | E27: 14146 | F27: 171.922 | G27: -0.83316526 | H27: 25.636084
A28: 26 | B28: 22 SPL A Path O 14A | C28: 0.212 | D28: 6 | E28: 20912 | F28: 263.157
A29: 26 | B29: 22 SPL A Path O 14A | C29: 0.212 | D29: 7 | E29: 19518 | F29: 247.169 | G29: -0.84528089 | H29: 25.661923
A30: 27 | B30: 23 SPL A Path O 15A | C30: 0.201 | D30: 6 | E30: 14414 | F30: 178.495
A31: 27 | B31: 23 SPL A Path O 15A | C31: 0.201 | D31: 7 | E31: 13351 | F31: 167.663 | G31: -1.0616512 | H31: 25.807917
A32: 28 | B32: 24 SPL A Path O 16A | C32: 0.253 | D32: 6 | E32: 24173 | F32: 300.878
A33: 28 | B33: 24 SPL A Path O 16A | C33: 0.253 | D33: 7 | E33: 22622 | F33: 279.787 | G33: -0.92298898 | H33: 25.881101
A34: 29 | B34: 25 SPL A Path O 17A | C34: 0.204 | D34: 6 | E34: 22302 | F34: 277.305
A35: 29 | B35: 25 SPL A Path O 17A | C35: 0.204 | D35: 7 | E35: 20546 | F35: 256.603 | G35: -0.97916177 | H35: 25.991699
A36: 30 | B36: 26 SPL A Path O 18A | C36: 0.224 | D36: 6 | E36: 21565 | F36: 265.621
A37: 30 | B37: 26 SPL A Path O 18A | C37: 0.224 | D37: 7 | E37: 20318 | F37: 250.738 | G37: -0.70754726 | H37: 25.694927
A38: 31 | B38: 27 SPL A Path O 19A | C38: 0.24 | D38: 6 | E38: 13784 | F38: 175.055
A39: 31 | B39: 27 SPL A Path O 19A | C39: 0.24 | D39: 7 | E39: 12821 | F39: 162.798 | G39: -0.54730034 | H39: 25.783489
A40: 32 | B40: 28 SPL A Path O 20A | C40: 0.234 | D40: 6 | E40: 12615 | F40: 155.085
A41: 32 | B41: 28 SPL A Path O 20A | C41: 0.234 | D41: 7 | E41: 11872 | F41: 145.224 | G41: -0.95953835 | H41: 25.520387
...

Sheet RAW_Corrected
A1: Row | B1: Identifier 1 | C1: Identifier 2 | D1: Peak Nr | E1: Ampl 44 | F1: Area 44 | G1: d 13C/12C | H1: d 18O/16O | J1: d 13C/12C ave | K1: stnd dev | M1: Ave ampl 44 | N1: std dev amp 44 | P1: d 18O/16O ave | Q1: stnd dev | S1: d 13C/12C amp 44 Corr | T1: d 13C/12C drift Corr | W1: d 18O/16O Amp 44 Corr | X1: d 18O/16O Drift Corr | Z1: δ13C (PDB) | AA1: δ18O (SMOW)
A3: 2 | B3: NBS 18 | C3: 0.23 | D3: 6 | E3: 13350 | F3: 169.452 | G3: -4.729 | H3: 17.385
A4: 2 | B4: NBS 18 | C4: 0.23 | D4: 7 | E4: 12410 | F4: 157.446 | G4: -4.666 | H4: 17.391 | J4: =AVERAGE(G3:G4) -> -4.6975 | K4: =STDEV(G3:G4) -> 0.044547727 | M4: =AVERAGE(E3:E4) -> 12880 | N4: =STDEV(E3:E4) -> 664.68037 | P4: =AVERAGE(H3:H4) -> 17.388 | Q4: =STDEV(H3:H4) -> 0.0042426407 | S4: =J4-(M4-Standards!$N$124)*Standards!$AA$55 -> -4.681878 | T4: =S4-(A4-Standards!$A$124)*Standards!$AA$4 -> -4.6472692 | W4: =P4-(M4-Standards!$N$124)*Standards!$AL$54 -> 17.369254 | X4: =W4-(A4-Standards!$A$124)*Standards!$AL$5 -> 17.373803 | Z4: =(T4*Standards!$O$159)+Standards!$O$160 -> -5.0061492 | AA4: =(X4*Standards!$U$159)+Standards!$U$160 -> 7.2640639
A5: 3 | B5: NBS18 | C5: 0.248 | D5: 6 | E5: 15170 | F5: 185.483 | G5: -4.729 | H5: 17.3
A6: 3 | B6: NBS18 | C6: 0.248 | D6: 7 | E6: 14309 | F6: 173.645 | G6: -4.677 | H6: 17.324 | J6: =AVERAGE(G5:G6) -> -4.703 | K6: =STDEV(G5:G6) -> 0.036769553 | M6: =AVERAGE(E5:E6) -> 14739.5 | N6: =STDEV(E5:E6) -> 608.81894 | P6: =AVERAGE(H5:H6) -> 17.312 | Q6: =STDEV(H5:H6) -> 0.016970563 | S6: =J6-(M6-Standards!$N$124)*Standards!$AA$55 -> -4.7106218 | T6: =S6-(A6-Standards!$A$124)*Standards!$AA$4 -> -4.6764389 | W6: =P6-(M6-Standards!$N$124)*Standards!$AL$54 -> 17.321146 | X6: =W6-(A6-Standards!$A$124)*Standards!$AL$5 -> 17.32564 | Z6: =(T6*Standards!$O$159)+Standards!$O$160 -> -5.0355364 | AA6: =(X6*Standards!$U$159)+Standards!$U$160 -> 7.2168583
A7: 4 | B7: NBS18 | C7: 0.258 | D7: 6 | E7: 15628 | F7: 198.581 | G7: -4.658 | H7: 17.243 | X7: .
A8: 4 | B8: NBS18 | C8: 0.258 | D8: 7 | E8: 14585 | F8: 184.826 | G8: -4.618 | H8: 17.258 | J8: =AVERAGE(G7:G8) -> -4.638 | K8: =STDEV(G7:G8) -> 0.028284271 | M8: =AVERAGE(E7:E8) -> 15106.5 | N8: =STDEV(E7:E8) -> 737.51237 | P8: =AVERAGE(H7:H8) -> 17.2505 | Q8: =STDEV(H7:H8) -> 0.010606602 | S8: =J8-(M8-Standards!$N$124)*Standards!$AA$55 -> -4.6502093 | T8: =S8-(A8-Standards!$A$124)*Standards!$AA$4 -> -4.6164524 | W8: =P8-(M8-Standards!$N$124)*Standards!$AL$54 -> 17.265151 | X8: =W8-(A8-Standards!$A$124)*Standards!$AL$5 -> 17.269589 | Z8: =(T8*Standards!$O$159)+Standards!$O$160 -> -4.9751028 | AA8: =(X8*Standards!$U$159)+Standards!$U$160 -> 7.161922
A9: 5 | B9: NBS18 | C9: 0.246 | D9: 6 | E9: 17291 | F9: 208.851 | G9: -4.701 | H9: 17.2
A10: 5 | B10: NBS18 | C10: 0.246 | D10: 7 | E10: 16186 | F10: 197.149 | G10: -4.746 | H10: 17.236 | J10: =AVERAGE(G9:G10) -> -4.7235 | K10: =STDEV(G9:G10) -> 0.031819805 | M10: =AVERAGE(E9:E10) -> 16738.5 | N10: =STDEV(E9:E10) -> 781.35299 | P10: =AVERAGE(H9:H10) -> 17.218 | Q10: =STDEV(H9:H10) -> 0.025455844 | S10: =J10-(M10-Standards!$N$124)*Standards!$AA$55 -> -4.7561093 | T10: =S10-(A10-Standards!$A$124)*Standards!$AA$4 -> -4.7227784 | W10: =P10-(M10-Standards!$N$124)*Standards!$AL$54 -> 17.257131 | X10: =W10-(A10-Standards!$A$124)*Standards!$AL$5 -> 17.261513 | Z10: =(T10*Standards!$O$159)+Standards!$O$160 -> -5.0822212 | AA10: =(X10*Standards!$U$159)+Standards!$U$160 -> 7.1540066
A11: 6 | B11: NBS 19 | C11: 0.22 | D11: 6 | E11: 13590 | F11: 172.613 | G11: 2.212 | H11: 39.091
A12: 6 | B12: NBS 19 | C12: 0.22 | D12: 7 | E12: 12673 | F12: 160.447 | G12: 2.265 | H12: 39.105 | J12: =AVERAGE(G11:G12) -> 2.2385 | K12: =STDEV(G11:G12) -> 0.037476659 | M12: =AVERAGE(E11:E12) -> 13131.5 | N12: =STDEV(E11:E12) -> 648.41692 | P12: =AVERAGE(H11:H12) -> 39.098 | Q12: =STDEV(H11:H12) -> 0.0098994949 | S12: =J12-(M12-Standards!$N$124)*Standards!$AA$55 -> 2.2509782 | T12: =S12-(A12-Standards!$A$124)*Standards!$AA$4 -> 2.2838831 | W12: =P12-(M12-Standards!$N$124)*Standards!$AL$54 -> 39.083026 | X12: =W12-(A12-Standards!$A$124)*Standards!$AL$5 -> 39.087352 | Z12: =(T12*Standards!$O$159)+Standards!$O$160 -> 1.976658 | AA12: =(X12*Standards!$U$159)+Standards!$U$160 -> 28.545773
A13: 7 | B13: NBS 19 | C13: 0.286 | D13: 6 | E13: 20377 | F13: 248.591 | G13: 2.333 | H13: 39.058
A14: 7 | B14: NBS 19 | C14: 0.286 | D14: 7 | E14: 18792 | F14: 230.568 | G14: 2.386 | H14: 39.059 | J14: =AVERAGE(G13:G14) -> 2.3595 | K14: =STDEV(G13:G14) -> 0.037476659 | M14: =AVERAGE(E13:E14) -> 19584.5 | N14: =STDEV(E13:E14) -> 1120.7642 | P14: =AVERAGE(H13:H14) -> 39.0585 | Q14: =STDEV(H13:H14) -> 0.00070710678 | S14: =J14-(M14-Standards!$N$124)*Standards!$AA$55 -> 2.2913157 | T14: =S14-(A14-Standards!$A$124)*Standards!$AA$4 -> 2.3237946 | W14: =P14-(M14-Standards!$N$124)*Standards!$AL$54 -> 39.140321 | X14: =W14-(A14-Standards!$A$124)*Standards!$AL$5 -> 39.144591 | Z14: =(T14*Standards!$O$159)+Standards!$O$160 -> 2.016867 | AA14: =(X14*Standards!$U$159)+Standards!$U$160 -> 28.601873
A15: 8 | B15: NBS 19 | C15: 0.286 | D15: 6 | E15: 17177 | F15: 215.748 | G15: 2.298 | H15: 39.043
A16: 8 | B16: NBS 19 | C16: 0.286 | D16: 7 | E16: 16128 | F16: 203.088 | G16: 2.269 | H16: 39.077 | J16: =AVERAGE(G15:G16) -> 2.2835 | K16: =STDEV(G15:G16) -> 0.020506097 | M16: =AVERAGE(E15:E16) -> 16652.5 | N16: =STDEV(E15:E16) -> 741.75501 | P16: =AVERAGE(H15:H16) -> 39.06 | Q16: =STDEV(H15:H16) -> 0.024041631 | S16: =J16-(M16-Standards!$N$124)*Standards!$AA$55 -> 2.2519657 | T16: =S16-(A16-Standards!$A$124)*Standards!$AA$4 -> 2.2840186 | W16: =P16-(M16-Standards!$N$124)*Standards!$AL$54 -> 39.097841 | X16: =W16-(A16-Standards!$A$124)*Standards!$AL$5 -> 39.102055 | Z16: =(T16*Standards!$O$159)+Standards!$O$160 -> 1.9767945 | AA16: =(X16*Standards!$U$159)+Standards!$U$160 -> 28.560183
A17: 9 | B17: NBS 19 | C17: 0.216 | D17: 6 | E17: 11846 | F17: 150.025 | G17: 2.21 | H17: 39.246
A18: 9 | B18: NBS 19 | C18: 0.216 | D18: 7 | E18: 10987 | F18: 139.3 | G18: 2.263 | H18: 39.241 | J18: =AVERAGE(G17:G18) -> 2.2365 | K18: =STDEV(G17:G18) -> 0.037476659 | M18: =AVERAGE(E17:E18) -> 11416.5 | N18: =STDEV(E17:E18) -> 607.40473 | P18: =AVERAGE(H17:H18) -> 39.2435 | Q18: =STDEV(H17:H18) -> 0.0035355339 | S18: =J18-(M18-Standards!$N$124)*Standards!$AA$55 -> 2.2704157 | T18: =S18-(A18-Standards!$A$124)*Standards!$AA$4 -> 2.3020426 | W18: =P18-(M18-Standards!$N$124)*Standards!$AL$54 -> 39.202801 | X18: =W18-(A18-Standards!$A$124)*Standards!$AL$5 -> 39.206959 | Z18: =(T18*Standards!$O$159)+Standards!$O$160 -> 1.9949529 | AA18: =(X18*Standards!$U$159)+Standards!$U$160 -> 28.663001
A19: 10 | B19: UTM | C19: 0.268 | D19: 6 | E19: 14953 | F19: 183.512 | G19: 4.629 | H19: 36.991
A20: 10 | B20: UTM | C20: 0.268 | D20: 7 | E20: 14114 | F20: 171.817 | G20: 4.728 | H20: 37.025 | J20: =AVERAGE(G19:G20) -> 4.6785 | K20: =STDEV(G19:G20) -> 0.070003571 | M20: =AVERAGE(E19:E20) -> 14533.5 | N20: =STDEV(E19:E20) -> 593.26259 | P20: =AVERAGE(H19:H20) -> 37.008 | Q20: =STDEV(H19:H20) -> 0.024041631 | S20: =J20-(M20-Standards!$N$124)*Standards!$AA$55 -> 4.6734532 | T20: =S20-(A20-Standards!$A$124)*Standards!$AA$4 -> 4.7046541 | W20: =P20-(M20-Standards!$N$124)*Standards!$AL$54 -> 37.014056 | X20: =W20-(A20-Standards!$A$124)*Standards!$AL$5 -> 37.018158 | Z20: =(T20*Standards!$O$159)+Standards!$O$160 -> 4.41547 | AA20: =(X20*Standards!$U$159)+Standards!$U$160 -> 26.517731
A21: 11 | B21: UTM | C21: 0.224 | D21: 6 | E21: 11903 | F21: 152.077 | G21: 4.725 | H21: 37.112
A22: 11 | B22: UTM | C22: 0.224 | D22: 7 | E22: 11107 | F22: 141.435 | G22: 4.786 | H22: 37.146 | J22: =AVERAGE(G21:G22) -> 4.7555 | K22: =STDEV(G21:G22) -> 0.043133514 | M22: =AVERAGE(E21:E22) -> 11505 | N22: =STDEV(E21:E22) -> 562.857 | P22: =AVERAGE(H21:H22) -> 37.129 | Q22: =STDEV(H21:H22) -> 0.024041631 | S22: =J22-(M22-Standards!$N$124)*Standards!$AA$55 -> 4.7883095 | T22: =S22-(A22-Standards!$A$124)*Standards!$AA$4 -> 4.8190843 | W22: =P22-(M22-Standards!$N$124)*Standards!$AL$54 -> 37.089629 | X22: =W22-(A22-Standards!$A$124)*Standards!$AL$5 -> 37.093674 | Z22: =(T22*Standards!$O$159)+Standards!$O$160 -> 4.5307531 | AA22: =(X22*Standards!$U$159)+Standards!$U$160 -> 26.591746
A23: 12 | B23: UTM | C23: 0.22 | D23: 6 | E23: 12846 | F23: 156.389 | G23: 4.641 | H23: 37.003
A24: 12 | B24: UTM | C24: 0.22 | D24: 7 | E24: 12045 | F24: 145.945 | G24: 4.737 | H24: 37.001 | J24: =AVERAGE(G23:G24) -> 4.689 | K24: =STDEV(G23:G24) -> 0.067882251 | M24: =AVERAGE(E23:E24) -> 12445.5 | N24: =STDEV(E23:E24) -> 566.39253 | P24: =AVERAGE(H23:H24) -> 37.002 | Q24: =STDEV(H23:H24) -> 0.0014142136 | S24: =J24-(M24-Standards!$N$124)*Standards!$AA$55 -> 4.7100532 | T24: =S24-(A24-Standards!$A$124)*Standards!$AA$4 -> 4.7404021 | W24: =P24-(M24-Standards!$N$124)*Standards!$AL$54 -> 36.976736 | X24: =W24-(A24-Standards!$A$124)*Standards!$AL$5 -> 36.980726 | Z24: =(T24*Standards!$O$159)+Standards!$O$160 -> 4.4514845 | AA24: =(X24*Standards!$U$159)+Standards!$U$160 -> 26.481043
A25: 13 | B25: 12 SPL A Path O 3A | C25: 0.208 | D25: 6 | E25: 15333 | F25: 194.652 | G25: -0.52 | H25: 36.024
A26: 13 | B26: 12 SPL A Path O 3A | C26: 0.208 | D26: 7 | E26: 14281 | F26: 180.81 | G26: -0.471 | H26: 36.076 | J26: =AVERAGE(G25:G26) -> -0.4955 | K26: =STDEV(G25:G26) -> 0.034648232 | M26: =AVERAGE(E25:E26) -> 14807 | N26: =STDEV(E25:E26) -> 743.87633 | P26: =AVERAGE(H25:H26) -> 36.05 | Q26: =STDEV(H25:H26) -> 0.036769553 | S26: =J26-(M26-Standards!$N$124)*Standards!$AA$55 -> -0.50396552 | T26: =S26-(A26-Standards!$A$124)*Standards!$AA$4 -> -0.47404269 | W26: =P26-(M26-Standards!$N$124)*Standards!$AL$54 -> 36.060159 | X26: =W26-(A26-Standards!$A$124)*Standards!$AL$5 -> 36.064092 | Z26: =(T26*Standards!$O$159)+Standards!$O$160 -> -0.8018214 | AA26: =(X26*Standards!$U$159)+Standards!$U$160 -> 25.58264
A27: 14 | B27: 12 SPL A Path O 4A | C27: 0.251 | D27: 6 | E27: 12939 | F27: 157.223 | G27: -0.959 | H27: 36.11
A28: 14 | B28: 12 SPL A Path O 4A | C28: 0.251 | D28: 7 | E28: 12052 | F28: 146.341 | G28: -0.853 | H28: 36.175 | J28: =AVERAGE(G27:G28) -> -0.906 | K28: =STDEV(G27:G28) -> 0.074953319 | M28: =AVERAGE(E27:E28) -> 12495.5 | N28: =STDEV(E27:E28) -> 627.20371 | P28: =AVERAGE(H27:H28) -> 36.1425 | Q28: =STDEV(H27:H28) -> 0.045961941 | S28: =J28-(M28-Standards!$N$124)*Standards!$AA$55 -> -0.88557177 | T28: =S28-(A28-Standards!$A$124)*Standards!$AA$4 -> -0.85607494 | W28: =P28-(M28-Standards!$N$124)*Standards!$AL$54 -> 36.117986 | X28: =W28-(A28-Standards!$A$124)*Standards!$AL$5 -> 36.121864 | Z28: =(T28*Standards!$O$159)+Standards!$O$160 -> -1.1867008 | AA28: =(X28*Standards!$U$159)+Standards!$U$160 -> 25.639263
A29: 15 | B29: 12 SPL A Path O 5A | C29: 0.249 | D29: 6 | E29: 17843 | F29: 225.331 | G29: -0.886 | H29: 36.155
A30: 15 | B30: 12 SPL A Path O 5A | C30: 0.249 | D30: 7 | E30: 16673 | F30: 212.049 | G30: -0.92 | H30: 36.253 | J30: =AVERAGE(G29:G30) -> -0.903 | K30: =STDEV(G29:G30) -> 0.024041631 | M30: =AVERAGE(E29:E30) -> 17258 | N30: =STDEV(E29:E30) -> 827.31493 | P30: =AVERAGE(H29:H30) -> 36.204 | Q30: =STDEV(H29:H30) -> 0.069296465 | S30: =J30-(M30-Standards!$N$124)*Standards!$AA$55 -> -0.94210302 | T30: =S30-(A30-Standards!$A$124)*Standards!$AA$4 -> -0.91303219 | W30: =P30-(M30-Standards!$N$124)*Standards!$AL$54 -> 36.250924 | X30: =W30-(A30-Standards!$A$124)*Standards!$AL$5 -> 36.254745 | Z30: =(T30*Standards!$O$159)+Standards!$O$160 -> -1.2440825 | AA30: =(X30*Standards!$U$159)+Standards!$U$160 -> 25.769501
A31: 16 | B31: 12 SPL A Path O 6A | C31: 0.245 | D31: 6 | E31: 23763 | F31: 288.937 | G31: -0.591 | H31: 36.06
A32: 16 | B32: 12 SPL A Path O 6A | C32: 0.245 | D32: 7 | E32: 21957 | F32: 270.774 | G32: -0.635 | H32: 36.158 | J32: =AVERAGE(G31:G32) -> -0.613 | K32: =STDEV(G31:G32) -> 0.031112698 | M32: =AVERAGE(E31:E32) -> 22860 | N32: =STDEV(E31:E32) -> 1277.0348 | P32: =AVERAGE(H31:H32) -> 36.109 | Q32: =STDEV(H31:H32) -> 0.069296465 | S32: =J32-(M32-Standards!$N$124)*Standards!$AA$55 -> -0.72212802 | T32: =S32-(A32-Standards!$A$124)*Standards!$AA$4 -> -0.69348319 | W32: =P32-(M32-Standards!$N$124)*Standards!$AL$54 -> 36.239954 | X32: =W32-(A32-Standards!$A$124)*Standards!$AL$5 -> 36.243719 | Z32: =(T32*Standards!$O$159)+Standards!$O$160 -> -1.0228973 | AA32: =(X32*Standards!$U$159)+Standards!$U$160 -> 25.758695
A33: 17 | B33: 12 SPL A Path O 7A | C33: 0.233 | D33: 6 | E33: 19610 | F33: 244.941 | G33: -0.637 | H33: 36.154
A34: 17 | B34: 12 SPL A Path O 7A | C34: 0.233 | D34: 7 | E34: 18377 | F34: 227.759 | G34: -0.614 | H34: 36.168 | J34: =AVERAGE(G33:G34) -> -0.6255 | K34: =STDEV(G33:G34) -> 0.016263456 | M34: =AVERAGE(E33:E34) -> 18993.5 | N34: =STDEV(E33:E34) -> 871.86266 | P34: =AVERAGE(H33:H34) -> 36.161 | Q34: =STDEV(H33:H34) -> 0.0098994949 | S34: =J34-(M34-Standards!$N$124)*Standards!$AA$55 -> -0.68629677 | T34: =S34-(A34-Standards!$A$124)*Standards!$AA$4 -> -0.65807794 | W34: =P34-(M34-Standards!$N$124)*Standards!$AL$54 -> 36.233956 | X34: =W34-(A34-Standards!$A$124)*Standards!$AL$5 -> 36.237666 | Z34: =(T34*Standards!$O$159)+Standards!$O$160 -> -0.98722819 | AA34: =(X34*Standards!$U$159)+Standards!$U$160 -> 25.752761
A35: 18 | B35: 12 SPL A Path O 8A | C35: 0.246 | D35: 6 | E35: 18516 | F35: 232.02 | G35: -0.727 | H35: 36.283
A36: 18 | B36: 12 SPL A Path O 8A | C36: 0.246 | D36: 7 | E36: 17131 | F36: 215.102 | G36: -0.789 | H36: 36.183 | J36: =AVERAGE(G35:G36) -> -0.758 | K36: =STDEV(G35:G36) -> 0.04384062 | M36: =AVERAGE(E35:E36) -> 17823.5 | N36: =STDEV(E35:E36) -> 979.34289 | P36: =AVERAGE(H35:H36) -> 36.233 | Q36: =STDEV(H35:H36) -> 0.070710678 | S36: =J36-(M36-Standards!$N$124)*Standards!$AA$55 -> -0.80417177 | T36: =S36-(A36-Standards!$A$124)*Standards!$AA$4 -> -0.77637894 | W36: =P36-(M36-Standards!$N$124)*Standards!$AL$54 -> 36.288406 | X36: =W36-(A36-Standards!$A$124)*Standards!$AL$5 -> 36.29206 | Z36: =(T36*Standards!$O$159)+Standards!$O$160 -> -1.1064108 | AA36: =(X36*Standards!$U$159)+Standards!$U$160 -> 25.806074
A37: 19 | B37: 12 SPL A Path O 9A | C37: 0.213 | D37: 6 | E37: 14870 | F37: 182.829 | G37: -0.843 | H37: 36.125
A38: 19 | B38: 12 SPL A Path O 9A | C38: 0.213 | D38: 7 | E38: 14001 | F38: 171 | G38: -0.778 | H38: 36.161 | J38: =AVERAGE(G37:G38) -> -0.8105 | K38: =STDEV(G37:G38) -> 0.045961941 | M38: =AVERAGE(E37:E38) -> 14435.5 | N38: =STDEV(E37:E38) -> 614.47579 | P38: =AVERAGE(H37:H38) -> 36.143 | Q38: =STDEV(H37:H38) -> 0.025455844 | S38: =J38-(M38-Standards!$N$124)*Standards!$AA$55 -> -0.81432177 | T38: =S38-(A38-Standards!$A$124)*Standards!$AA$4 -> -0.78695494 | W38: =P38-(M38-Standards!$N$124)*Standards!$AL$54 -> 36.147586 | X38: =W38-(A38-Standards!$A$124)*Standards!$AL$5 -> 36.151184 | Z38: =(T38*Standards!$O$159)+Standards!$O$160 -> -1.1170657 | AA38: =(X38*Standards!$U$159)+Standards!$U$160 -> 25.667999
A39: 20 | B39: 12 SPL A Path O 10A | C39: 0.248 | D39: 6 | E39: 16047 | F39: 203.691 | G39: -0.544 | H39: 36.129
A40: 20 | B40: 12 SPL A Path O 10A | C40: 0.248 | D40: 7 | E40: 14981 | F40: 191.732 | G40: -0.556 | H40: 36.137 | J40: =AVERAGE(G39:G40) -> -0.55 | K40: =STDEV(G39:G40) -> 0.0084852814 | M40: =AVERAGE(E39:E40) -> 15514 | N40: =STDEV(E39:E40) -> 753.77583 | P40: =AVERAGE(H39:H40) -> 36.133 | Q40: =STDEV(H39:H40) -> 0.0056568542 | S40: =J40-(M40-Standards!$N$124)*Standards!$AA$55 -> -0.56730302 | T40: =S40-(A40-Standards!$A$124)*Standards!$AA$4 -> -0.54036219 | W40: =P40-(M40-Standards!$N$124)*Standards!$AL$54 -> 36.153764 | X40: =W40-(A40-Standards!$A$124)*Standards!$AL$5 -> 36.157305 | Z40: =(T40*Standards!$O$159)+Standards!$O$160 -> -0.86863515 | AA40: =(X40*Standards!$U$159)+Standards!$U$160 -> 25.673999
A41: 21 | B41: 12 SPL A Path O 11A | C41: 0.238 | D41: 6 | E41: 17997 | F41: 218.108 | G41: -0.827 | H41: 35.995
...

Sheet 2-Full_Sorted
A1: Row | B1: Identifier 1 | C1: Identifier 2 | D1: Peak Nr | E1: Ampl 44 | F1: Area 44 | G1: d 13C/12C | H1: d 18O/16O
A3: 2 | B3: NBS 18 | C3: 0.23 | D3: 6 | E3: 13350 | F3: 169.452 | G3: -4.729 | H3: 17.385
A4: 2 | B4: NBS 18 | C4: 0.23 | D4: 7 | E4: 12410 | F4: 157.446 | G4: -4.666 | H4: 17.391
A5: 3 | B5: NBS18 | C5: 0.248 | D5: 6 | E5: 15170 | F5: 185.483 | G5: -4.729 | H5: 17.3
A6: 3 | B6: NBS18 | C6: 0.248 | D6: 7 | E6: 14309 | F6: 173.645 | G6: -4.677 | H6: 17.324
A7: 4 | B7: NBS18 | C7: 0.258 | D7: 6 | E7: 15628 | F7: 198.581 | G7: -4.658 | H7: 17.243
A8: 4 | B8: NBS18 | C8: 0.258 | D8: 7 | E8: 14585 | F8: 184.826 | G8: -4.618 | H8: 17.258
A9: 5 | B9: NBS18 | C9: 0.246 | D9: 6 | E9: 17291 | F9: 208.851 | G9: -4.701 | H9: 17.2
A10: 5 | B10: NBS18 | C10: 0.246 | D10: 7 | E10: 16186 | F10: 197.149 | G10: -4.746 | H10: 17.236
A11: 6 | B11: NBS 19 | C11: 0.22 | D11: 6 | E11: 13590 | F11: 172.613 | G11: 2.212 | H11: 39.091
A12: 6 | B12: NBS 19 | C12: 0.22 | D12: 7 | E12: 12673 | F12: 160.447 | G12: 2.265 | H12: 39.105
A13: 7 | B13: NBS 19 | C13: 0.286 | D13: 6 | E13: 20377 | F13: 248.591 | G13: 2.333 | H13: 39.058
A14: 7 | B14: NBS 19 | C14: 0.286 | D14: 7 | E14: 18792 | F14: 230.568 | G14: 2.386 | H14: 39.059
... A234: 118 | B234: 12 SPL A4 Path H 69A | C234: 0.254 | D234: 7 | E234: 13419 | F234: 169.817 | G234: -1.271 | H234: 36.062
A235: 119 | B235: UTM | D235: 6 | E235: 14949 | F235: 184.742 | G235: 4.737 | H235: 36.845
A236: 119 | B236: UTM | D236: 7 | E236: 14087 | F236: 172.649 | G236: 4.805 | H236: 36.916
A237: 120 | B237: UTM | D237: 6 | E237: 15186 | F237: 192.816 | G237: 4.78 | H237: 36.985
A238: 120 | B238: UTM | D238: 7 | E238: 14089 | F238: 178.972 | G238: 4.846 | H238: 37.047
A239: 121 | B239: 12 SPL A4 Path H 70A | C239: 0.242 | D239: 6 | E239: 14255 | F239: 174.426 | G239: -1.532 | H239: 35.9
A240: 121 | B240: 12 SPL A4 Path H 70A | C240: 0.242 | D240: 7 | E240: 13433 | F240: 163.215 | G240: -1.455 | H240: 35.913
A241: 122 | B241: 12 SPL A4 Path H 71A | C241: 0.232 | D241: 6 | E241: 13764 | F241: 175.476 | G241: -1.687 | H241: 35.797
A242: 122 | B242: 12 SPL A4 Path H 71A | C242: 0.232 | D242: 7 | E242: 12830 | F242: 163.132 | G242: -1.627 | H242: 35.844
A243: 123 | B243: 12 SPL A4 Path H 72A | C243: 0.244 | D243: 6 | E243: 15705 | F243: 190.046 | G243: -1.808 | H243: 35.676
A244: 123 | B244: 12 SPL A4 Path H 72A | C244: 0.244 | D244: 7 | E244: 14676 | F244: 177.412 | G244: -1.766 | H244: 35.698
A245: 124 | B245: 12 SPL A4 Path H 73A | C245: 0.256 | D245: 6 | E245: 13973 | F245: 177.645 | G245: -1.83 | H245: 35.678
A246: 124 | B246: 12 SPL A4 Path H 73A | C246: 0.256 | D246: 7 | E246: 13030 | F246: 165.059 | G246: -1.788 | H246: 35.727
A247: 125 | B247: 12 SPL A4 Path H 74A | C247: 0.266 | D247: 6 | E247: 17454 | F247: 212.159 | G247: -2.379 | H247: 35.888
A248: 125 | B248: 12 SPL A4 Path H 74A | C248: 0.266 | D248: 7 | E248: 16137 | F248: 199.007 | G248: -2.411 | H248: 35.935
A249: 126 | B249: 12 SPL A4 Path H 75A | C249: 0.234 | D249: 6 | E249: 12909 | F249: 163.914 | G249: -2.3 | H249: 36.015
A250: 126 | B250: 12 SPL A4 Path H 75A | C250: 0.234 | D250: 7 | E250: 12033 | F250: 152.156 | G250: -2.216 | H250: 36.054
... A258: 130 | B258: 12 SPL A4 Path H 79A | C258: 0.238 | D258: 7 | E258: 12152 | F258: 151.325 | G258: -1.885 | H258: 35.793
A259: 131 | B259: UTM | D259: 6 | E259: 16505 | F259: 207.922 | G259: 4.807 | H259: 36.99
A260: 131 | B260: UTM | D260: 7 | E260: 15325 | F260: 195.234 | G260: 4.794 | H260: 37.008
A261: 132 | B261: UTM | D261: 6 | E261: 19965 | F261: 243.293 | G261: 4.862 | H261: 36.822
A262: 132 | B262: UTM | D262: 7 | E262: 18790 | F262: 230.378 | G262: 4.797 | H262: 36.91
A263: 133 | B263: 12 SPL A4 Path H 80A | C263: 0.24 | D263: 6 | E263: 13210 | F263: 168.569 | G263: -1.884 | H263: 35.708
A264: 133 | B264: 12 SPL A4 Path H 80A | C264: 0.24 | D264: 7 | E264: 12307 | F264: 156.525 | G264: -1.824 | H264: 35.757
A265: 134 | B265: 12 SPL A4 Path H 81A | C265: 0.31 | D265: 6 | E265: 18688 | F265: 226.232 | G265: -1.882 | H265: 35.661
A266: 134 | B266: 12 SPL A4 Path H 81A | C266: 0.31 | D266: 7 | E266: 17582 | F266: 213.834 | G266: -1.919 | H266: 35.693
A267: 135 | B267: 12 SPL A4 Path H 82A | C267: 0.248 | D267: 6 | E267: 13674 | F267: 174.131 | G267: -2.072 | H267: 35.897
...

Sheet Standards
A1: Row | B1: Line | C1: Identifier 1 | D1: Identifier 2 | E1: Peak Nr | F1: Ampl 44 | G1: Area 44 | H1: d 13C/12C | I1: d 18O/16O | K1: d 13C/12C ave | L1: stnd dev | N1: Ave Amp 44 | P1: d 18O/16O ave | Q1: stnd dev | T1: d 13C/12C amp 44 Corr | U1: d 13C/12C drift Corr | X1: d 18O/16O amp 44 Corr | Y1: d 18O/16O drift Corr
A3: 2 | B3: =A3 -> 2 | C3: NBS 18 | D3: 0.23 | E3: 6 | F3: 13350 | G3: 169.452 | H3: -4.729 | I3: 17.385 | K3: =AVERAGE(H3:H4) -> -4.6975 | L3: =STDEV(H3:H4) -> 0.044547727 | N3: =AVERAGE(F3,F4) -> 12880 | P3: =AVERAGE(I3:I4) -> 17.388 | Q3: =STDEV(I3:I4) -> 0.0042426407 | T3: =K3-(N3-$N$124)*$AA$55 -> -4.681878 | U3: =T3-(B3-$A$124)*$AA$4 -> -4.6472692 | X3: =P3-(N3-$N$124)*$AL$54 -> 17.369254 | Y3: =X3-(B3-$A$124)*$AL$5 -> 17.373803
A4: 2 | B4: =A4 -> 2 | C4: NBS 18 | D4: 0.23 | E4: 7 | F4: 12410 | G4: 157.446 | H4: -4.666 | I4: 17.391 | AA4: 0.000426 | AL4: O drift
A5: 3 | B5: =A5 -> 3 | C5: NBS18 | D5: 0.248 | E5: 6 | F5: 15170 | G5: 185.483 | H5: -4.729 | I5: 17.3 | K5: =AVERAGE(H5:H6) -> -4.703 | L5: =STDEV(H5:H6) -> 0.036769553 | N5: =AVERAGE(F5,F6) -> 14739.5 | P5: =AVERAGE(I5:I6) -> 17.312 | Q5: =STDEV(I5:I6) -> 0.016970563 | T5: =K5-(N5-$N$124)*$AA$55 -> -4.7106218 | U5: =T5-(B5-$A$124)*$AA$4 -> -4.6764389 | X5: =P5-(N5-$N$124)*$AL$54 -> 17.321146 | Y5: =X5-(B5-$A$124)*$AL$5 -> 17.32564 | AL5: 5.6e-05
A6: 3 | B6: =A6 -> 3 | C6: NBS18 | D6: 0.248 | E6: 7 | F6: 14309 | G6: 173.645 | H6: -4.677 | I6: 17.324
A7: 4 | B7: =A7 -> 4 | C7: NBS18 | D7: 0.258 | E7: 6 | F7: 15628 | G7: 198.581 | H7: -4.658 | I7: 17.243 | K7: =AVERAGE(H7:H8) -> -4.638 | L7: =STDEV(H7:H8) -> 0.028284271 | N7: =AVERAGE(F7,F8) -> 15106.5 | P7: =AVERAGE(I7:I8) -> 17.2505 | Q7: =STDEV(I7:I8) -> 0.010606602 | T7: =K7-(N7-$N$124)*$AA$55 -> -4.6502093 | U7: =T7-(B7-$A$124)*$AA$4 -> -4.6164524 | X7: =P7-(N7-$N$124)*$AL$54 -> 17.265151 | Y7: =X7-(B7-$A$124)*$AL$5 -> 17.269589
A8: 4 | B8: =A8 -> 4 | C8: NBS18 | D8: 0.258 | E8: 7 | F8: 14585 | G8: 184.826 | H8: -4.618 | I8: 17.258
A9: 5 | B9: =A9 -> 5 | C9: NBS18 | D9: 0.246 | E9: 6 | F9: 17291 | G9: 208.851 | H9: -4.701 | I9: 17.2 | K9: =AVERAGE(H9:H10) -> -4.7235 | L9: =STDEV(H9:H10) -> 0.031819805 | N9: =AVERAGE(F9,F10) -> 16738.5 | P9: =AVERAGE(I9:I10) -> 17.218 | Q9: =STDEV(I9:I10) -> 0.025455844 | T9: =K9-(N9-$N$124)*$AA$55 -> -4.7561093 | U9: =T9-(B9-$A$124)*$AA$4 -> -4.7227784 | X9: =P9-(N9-$N$124)*$AL$54 -> 17.257131 | Y9: =X9-(B9-$A$124)*$AL$5 -> 17.261513
A10: 5 | B10: =A10 -> 5 | C10: NBS18 | D10: 0.246 | E10: 7 | F10: 16186 | G10: 197.149 | H10: -4.746 | I10: 17.236
K11: =AVERAGE(H11:H12) -> #DIV/0! | L11: =STDEV(H11:H12) -> #DIV/0! | N11: =AVERAGE(F11,F12) -> #DIV/0! | P11: =AVERAGE(I11:I12) -> #DIV/0! | Q11: =STDEV(I11:I12) -> #DIV/0! | T11: =U11-(N11-$N$124)*$AA$55 -> #DIV/0! | U11: =K11-(B11-$A$124)*$AA$4 -> #DIV/0! | X11: =P11-(N11-$N$124)*$AL$54 -> #DIV/0! | Y11: =P11-(B11-$A$124)*$AL$5 -> #DIV/0!
K13: =AVERAGE(H13:H14) -> #DIV/0! | L13: =STDEV(H13:H14) -> #DIV/0! | N13: =AVERAGE(F13,F14) -> #DIV/0! | P13: =AVERAGE(I13:I14) -> #DIV/0! | Q13: =STDEV(I13:I14) -> #DIV/0! | T13: =U13-(N13-$N$124)*$AA$55 -> #DIV/0! | U13: =K13-(B13-$A$124)*$AA$4 -> #DIV/0! | X13: =Y13-(N13-$N$124)*$AL$54 -> #DIV/0! | Y13: =P13-(B13-$A$124)*$AL$5 -> #DIV/0!
K15: =AVERAGE(H15:H16) -> #DIV/0! | L15: =STDEV(H15:H16) -> #DIV/0! | N15: =AVERAGE(F15,F16) -> #DIV/0! | P15: =AVERAGE(I15:I16) -> #DIV/0! | Q15: =STDEV(I15:I16) -> #DIV/0! | T15: =U15-(N15-$N$124)*$AA$55 -> #DIV/0! | U15: =K15-(B15-$A$124)*$AA$4 -> #DIV/0! | X15: =Y15-(N15-$N$124)*$AL$54 -> #DIV/0! | Y15: =P15-(B15-$A$124)*$AL$5 -> #DIV/0!
K17: =AVERAGE(H17:H18) -> #DIV/0! | L17: =STDEV(H17:H18) -> #DIV/0! | N17: =AVERAGE(F17,F18) -> #DIV/0! | P17: =AVERAGE(I17:I18) -> #DIV/0! | Q17: =STDEV(I17:I18) -> #DIV/0! | T17: =U17-(N17-$N$124)*$AA$55 -> #DIV/0! | U17: =K17-(B17-$A$124)*$AA$4 -> #DIV/0! | X17: =Y17-(N17-$N$124)*$AL$54 -> #DIV/0! | Y17: =P17-(B17-$A$124)*$AL$5 -> #DIV/0!
K21: =AVERAGE(K3:K9) -> -4.6905 | O21: Ave | P21: =AVERAGE(P3:P9) -> 17.292125 | S21: Ave | T21: =AVERAGE(T3:T9) -> -4.6997046 | U21: =AVERAGE(U3:U9) -> -4.6657348 | W21: Ave | X21: =AVERAGE(X3:X9) -> 17.30317 | Y21: =AVERAGE(Y3:Y9) -> 17.307636
K22: =STDEV(K3:K9) -> 0.036744614 | O22: Std Dev | P22: =STDEV(P3:P9) -> 0.074864739 | S22: Std Dev | T22: =STDEV(T3:T9) -> 0.044974978 | U22: =STDEV(U3:U9) -> 0.045233782 | W22: Std Dev | X22: =STDEV(X3:X9) -> 0.052456965 | Y22: =STDEV(Y3:Y9) -> 0.052526779
A25: 6 | B25: =A25 -> 6 | C25: NBS 19 | D25: 0.22 | E25: 6 | F25: 13590 | G25: 172.613 | H25: 2.212 | I25: 39.091 | K25: =AVERAGE(H25:H26) -> 2.2385 | L25: =STDEV(H25:H26) -> 0.037476659 | N25: =AVERAGE(F25,F26) -> 13131.5 | P25: =AVERAGE(I25:I26) -> 39.098 | Q25: =STDEV(I25:I26) -> 0.0098994949 | T25: =K25-(N25-$N$124)*$AA$55 -> 2.2509782 | U25: =T25-(B25-$A$124)*$AA$4 -> 2.2838831 | X25: =P25-(N25-$N$124)*$AL$54 -> 39.083026 | Y25: =X25-(B25-$A$124)*$AL$5 -> 39.087352
A26: 6 | B26: =A26 -> 6 | C26: NBS 19 | D26: 0.22 | E26: 7 | F26: 12673 | G26: 160.447 | H26: 2.265 | I26: 39.105
A27: 7 | B27: =A27 -> 7 | C27: NBS 19 | D27: 0.286 | E27: 6 | F27: 20377 | G27: 248.591 | H27: 2.333 | I27: 39.058 | K27: =AVERAGE(H27:H28) -> 2.3595 | L27: =STDEV(H27:H28) -> 0.037476659 | N27: =AVERAGE(F27,F28) -> 19584.5 | P27: =AVERAGE(I27:I28) -> 39.0585 | Q27: =STDEV(I27:I28) -> 0.00070710678 | T27: =K27-(N27-$N$124)*$AA$55 -> 2.2913157 | U27: =T27-(B27-$A$124)*$AA$4 -> 2.3237946 | X27: =P27-(N27-$N$124)*$AL$54 -> 39.140321 | Y27: =X27-(B27-$A$124)*$AL$5 -> 39.144591
A28: 7 | B28: =A28 -> 7 | C28: NBS 19 | D28: 0.286 | E28: 7 | F28: 18792 | G28: 230.568 | H28: 2.386 | I28: 39.059
A29: 8 | B29: =A29 -> 8 | C29: NBS 19 | D29: 0.286 | E29: 6 | F29: 17177 | G29: 215.748 | H29: 2.298 | I29: 39.043 | K29: =AVERAGE(H29:H30) -> 2.2835 | L29: =STDEV(H29:H30) -> 0.020506097 | N29: =AVERAGE(F29,F30) -> 16652.5 | P29: =AVERAGE(I29:I30) -> 39.06 | Q29: =STDEV(I29:I30) -> 0.024041631 | T29: =K29-(N29-$N$124)*$AA$55 -> 2.2519657 | U29: =T29-(B29-$A$124)*$AA$4 -> 2.2840186 | X29: =P29-(N29-$N$124)*$AL$54 -> 39.097841 | Y29: =X29-(B29-$A$124)*$AL$5 -> 39.102055
A30: 8 | B30: =A30 -> 8 | C30: NBS 19 | D30: 0.286 | E30: 7 | F30: 16128 | G30: 203.088 | H30: 2.269 | I30: 39.077
A31: 9 | B31: =A31 -> 9 | C31: NBS 19 | D31: 0.216 | E31: 6 | F31: 11846 | G31: 150.025 | H31: 2.21 | I31: 39.246 | K31: =AVERAGE(H31:H32) -> 2.2365 | L31: =STDEV(H31:H32) -> 0.037476659 | N31: =AVERAGE(F31,F32) -> 11416.5 | P31: =AVERAGE(I31:I32) -> 39.2435 | Q31: =STDEV(I31:I32) -> 0.0035355339 | T31: =K31-(N31-$N$124)*$AA$55 -> 2.2704157 | U31: =T31-(B31-$A$124)*$AA$4 -> 2.3020426 | X31: =P31-(N31-$N$124)*$AL$54 -> 39.202801 | Y31: =X31-(B31-$A$124)*$AL$5 -> 39.206959
A32: 9 | B32: =A32 -> 9 | C32: NBS 19 | D32: 0.216 | E32: 7 | F32: 10987 | G32: 139.3 | H32: 2.263 | I32: 39.241
K33: =AVERAGE(H33:H34) -> #DIV/0! | L33: =STDEV(H33:H34) -> #DIV/0! | N33: =AVERAGE(F33,F34) -> #DIV/0! | P33: =AVERAGE(I33:I34) -> #DIV/0! | Q33: =STDEV(I33:I34) -> #DIV/0! | T33: =U33-(N33-$N$124)*$AA$55 -> #DIV/0! | U33: =K33-(B33-$A$124)*$AA$4 -> #DIV/0! | X33: =Y33-(N33-$N$124)*$AL$54 -> #DIV/0! | Y33: =P33-(B33-$A$124)*$AL$5 -> #DIV/0!
K35: =AVERAGE(H35:H36) -> #DIV/0! | L35: =STDEV(H35:H36) -> #DIV/0! | N35: =AVERAGE(F35,F36) -> #DIV/0! | P35: =AVERAGE(I35:I36) -> #DIV/0! | Q35: =STDEV(I35:I36) -> #DIV/0! | T35: =U35-(N35-$N$124)*$AA$55 -> #DIV/0! | U35: =K35-(B35-$A$124)*$AA$4 -> #DIV/0! | X35: =Y35-(N35-$N$124)*$AL$54 -> #DIV/0! | Y35: =P35-(B35-$A$124)*$AL$5 -> #DIV/0!
K37: =AVERAGE(H37:H38) -> #DIV/0! | L37: =STDEV(H37:H38) -> #DIV/0! | N37: =AVERAGE(F37,F38) -> #DIV/0! | P37: =AVERAGE(I37:I38) -> #DIV/0! | Q37: =STDEV(I37:I38) -> #DIV/0! | T37: =U37-(N37-$N$124)*$AA$55 -> #DIV/0! | U37: =K37-(B37-$A$124)*$AA$4 -> #DIV/0! | X37: =Y37-(N37-$N$124)*$AL$54 -> #DIV/0! | Y37: =P37-(B37-$A$124)*$AL$5 -> #DIV/0!
K39: =AVERAGE(H39:H40) -> #DIV/0! | L39: =STDEV(H39:H40) -> #DIV/0! | N39: =AVERAGE(F39,F40) -> #DIV/0! | P39: =AVERAGE(I39:I40) -> #DIV/0! | Q39: =STDEV(I39:I40) -> #DIV/0! | T39: =U39-(N39-$N$124)*$AA$55 -> #DIV/0! | U39: =K39-(B39-$A$124)*$AA$4 -> #DIV/0! | X39: =Y39-(N39-$N$124)*$AL$54 -> #DIV/0! | Y39: =P39-(B39-$A$124)*$AL$5 -> #DIV/0!
K43: =AVERAGE(K25:K31) -> 2.2795 | O43: Ave | P43: =AVERAGE(P25:P31) -> 39.115 | S43: Ave | T43: =AVERAGE(T25:T31) -> 2.2661689 | U43: =AVERAGE(U25:U31) -> 2.2984347 | W43: Ave | X43: =AVERAGE(X25:X31) -> 39.130997 | Y43: =AVERAGE(Y25:Y31) -> 39.135239
K44: =STDEV(K25:K31) -> 0.057578931 | O44: Std Dev | P44: =STDEV(P25:P31) -> 0.087594711 | S44: Std Dev | T44: =STDEV(T25:T31) -> 0.018998992 | U44: =STDEV(U25:U31) -> 0.018935984 | W44: Std Dev | X44: =STDEV(X25:X31) -> 0.053675844 | Y44: =STDEV(Y25:Y31) -> 0.05362077
A49: 10 | B49: =A49 -> 10 | C49: UTM | D49: 0.268 | E49: 6 | F49: 14953 | G49: 183.512 | H49: 4.629 | I49: 36.991 | K49: =AVERAGE(H49:H50) -> 4.6785 | L49: =STDEV(H49:H50) -> 0.070003571 | N49: =AVERAGE(F49,F50) -> 14533.5 | P49: =AVERAGE(I49:I50) -> 37.008 | Q49: =STDEV(I49:I50) -> 0.024041631 | T49: =K49-(N49-$N$124)*$AA$55 -> 4.6734532 | U49: =T49-(B49-$A$124)*$AA$4 -> 4.7046541 | X49: =P49-(N49-$N$124)*$AL$54 -> 37.014056 | Y49: =X49-(B49-$A$124)*$AL$5 -> 37.018158
A50: 10 | B50: =A50 -> 10 | C50: UTM | D50: 0.268 | E50: 7 | F50: 14114 | G50: 171.817 | H50: 4.728 | I50: 37.025
A51: 11 | B51: =A51 -> 11 | C51: UTM | D51: 0.224 | E51: 6 | F51: 11903 | G51: 152.077 | H51: 4.725 | I51: 37.112 | K51: =AVERAGE(H51:H52) -> 4.7555 | L51: =STDEV(H51:H52) -> 0.043133514 | N51: =AVERAGE(F51,F52) -> 11505 | P51: =AVERAGE(I51:I52) -> 37.129 | Q51: =STDEV(I51:I52) -> 0.024041631 | T51: =K51-(N51-$N$124)*$AA$55 -> 4.7883095 | U51: =T51-(B51-$A$124)*$AA$4 -> 4.8190843 | X51: =P51-(N51-$N$124)*$AL$54 -> 37.089629 | Y51: =X51-(B51-$A$124)*$AL$5 -> 37.093674
A52: 11 | B52: =A52 -> 11 | C52: UTM | D52: 0.224 | E52: 7 | F52: 11107 | G52: 141.435 | H52: 4.786 | I52: 37.146
A53: 12 | B53: =A53 -> 12 | C53: UTM | D53: 0.22 | E53: 6 | F53: 12846 | G53: 156.389 | H53: 4.641 | I53: 37.003 | K53: =AVERAGE(H53:H54) -> 4.689 | L53: =STDEV(H53:H54) -> 0.067882251 | N53: =AVERAGE(F53,F54) -> 12445.5 | P53: =AVERAGE(I53:I54) -> 37.002 | Q53: =STDEV(I53:I54) -> 0.0014142136 | T53: =K53-(N53-$N$124)*$AA$55 -> 4.7100532 | U53: =T53-(B53-$A$124)*$AA$4 -> 4.7404021 | X53: =P53-(N53-$N$124)*$AL$54 -> 36.976736 | Y53: =X53-(B53-$A$124)*$AL$5 -> 36.980726 | AL53: O amp
A54: 12 | B54: =A54 -> 12 | C54: UTM | D54: 0.22 | E54: 7 | F54: 12045 | G54: 145.945 | H54: 4.737 | I54: 37.001 | AA54: C amp | AL54: -1.5e-05
A55: 23 | B55: =A55 -> 23 | C55: UTM | D55: 0.242 | E55: 6 | F55: 14249 | G55: 172.765 | H55: 4.723 | I55: 37.028 | K55: =AVERAGE(H55:H56) -> 4.736 | L55: =STDEV(H55:H56) -> 0.018384776 | N55: =AVERAGE(F55,F56) -> 13803.5 | P55: =AVERAGE(I55:I56) -> 37.0335 | Q55: =STDEV(I55:I56) -> 0.0077781746 | T55: =K55-(N55-$N$124)*$AA$55 -> 4.7400782 | U55: =T55-(B55-$A$124)*$AA$4 -> 4.7657411 | X55: =P55-(N55-$N$124)*$AL$54 -> 37.028606 | Y55: =X55-(B55-$A$124)*$AL$5 -> 37.03198 | AA55: 1.25e-05
A56: 23 | B56: =A56 -> 23 | C56: UTM | D56: 0.242 | E56: 7 | F56: 13358 | G56: 161.717 | H56: 4.749 | I56: 37.039
A57: 24 | B57: =A57 -> 24 | C57: UTM | D57: 0.25 | E57: 6 | F57: 13745 | G57: 175.069 | H57: 4.738 | I57: 36.983 | K57: =AVERAGE(H57:H58) -> 4.767 | L57: =STDEV(H57:H58) -> 0.041012193 | N57: =AVERAGE(F57,F58) -> 13291.5 | P57: =AVERAGE(I57:I58) -> 37.007 | Q57: =STDEV(I57:I58) -> 0.033941125 | T57: =K57-(N57-$N$124)*$AA$55 -> 4.7774782 | U57: =T57-(B57-$A$124)*$AA$4 -> 4.8027151 | X57: =P57-(N57-$N$124)*$AL$54 -> 36.994426 | Y57: =X57-(B57-$A$124)*$AL$5 -> 36.997744
A58: 24 | B58: =A58 -> 24 | C58: UTM | D58: 0.25 | E58: 7 | F58: 12838 | G58: 162.933 | H58: 4.796 | I58: 37.031
A59: 35 | B59: =A59 -> 35 | C59: UTM | D59: 0.274 | E59: 6 | F59: 14725 | G59: 187.218 | H59: 4.747 | I59: 36.978 | K59: =AVERAGE(H59:H60) -> 4.782 | L59: =STDEV(H59:H60) -> 0.049497475 | N59: =AVERAGE(F59,F60) -> 14228.5 | P59: =AVERAGE(I59:I60) -> 36.998 | Q59: =STDEV(I59:I60) -> 0.028284271 | T59: =K59-(N59-$N$124)*$AA$55 -> 4.7807657 | U59: =T59-(B59-$A$124)*$AA$4 -> 4.8013166 | X59: =P59-(N59-$N$124)*$AL$54 -> 36.999481 | Y59: =X59-(B59-$A$124)*$AL$5 -> 37.002183
...

Sheet 1-Sorted_standards
A1: Row | C1: Identifier 1 | D1: Identifier 2 | E1: Peak Nr | F1: Ampl 44 | G1: Area 44 | H1: d 13C/12C | I1: d 18O/16O
A3: 2 | B3: =A3 -> 2 | C3: NBS 18 | D3: 0.23 | E3: 6 | F3: 13350 | G3: 169.452 | H3: -4.729 | I3: 17.385
A4: 2 | B4: =A4 -> 2 | C4: NBS 18 | D4: 0.23 | E4: 7 | F4: 12410 | G4: 157.446 | H4: -4.666 | I4: 17.391
A5: 3 | B5: =A5 -> 3 | C5: NBS18 | D5: 0.248 | E5: 6 | F5: 15170 | G5: 185.483 | H5: -4.729 | I5: 17.3
A6: 3 | B6: =A6 -> 3 | C6: NBS18 | D6: 0.248 | E6: 7 | F6: 14309 | G6: 173.645 | H6: -4.677 | I6: 17.324
A7: 4 | B7: =A7 -> 4 | C7: NBS18 | D7: 0.258 | E7: 6 | F7: 15628 | G7: 198.581 | H7: -4.658 | I7: 17.243
A8: 4 | B8: =A8 -> 4 | C8: NBS18 | D8: 0.258 | E8: 7 | F8: 14585 | G8: 184.826 | H8: -4.618 | I8: 17.258
A9: 5 | B9: =A9 -> 5 | C9: NBS18 | D9: 0.246 | E9: 6 | F9: 17291 | G9: 208.851 | H9: -4.701 | I9: 17.2
A10: 5 | B10: =A10 -> 5 | C10: NBS18 | D10: 0.246 | E10: 7 | F10: 16186 | G10: 197.149 | H10: -4.746 | I10: 17.236
A11: 6 | B11: =A11 -> 6 | C11: NBS 19 | D11: 0.22 | E11: 6 | F11: 13590 | G11: 172.613 | H11: 2.212 | I11: 39.091
A12: 6 | B12: =A12 -> 6 | C12: NBS 19 | D12: 0.22 | E12: 7 | F12: 12673 | G12: 160.447 | H12: 2.265 | I12: 39.105
A13: 7 | B13: =A13 -> 7 | C13: NBS 19 | D13: 0.286 | E13: 6 | F13: 20377 | G13: 248.591 | H13: 2.333 | I13: 39.058
A14: 7 | B14: =A14 -> 7 | C14: NBS 19 | D14: 0.286 | E14: 7 | F14: 18792 | G14: 230.568 | H14: 2.386 | I14: 39.059
... A60: 108 | B60: =A60 -> 108 | C60: UTM | D60: 0.248 | E60: 7 | F60: 13110 | G60: 160.28 | H60: 4.717 | I60: 37.065
A61: 119 | B61: =A61 -> 119 | C61: UTM | E61: 6 | F61: 14949 | G61: 184.742 | H61: 4.737 | I61: 36.845
A62: 119 | B62: =A62 -> 119 | C62: UTM | E62: 7 | F62: 14087 | G62: 172.649 | H62: 4.805 | I62: 36.916
A63: 120 | B63: =A63 -> 120 | C63: UTM | E63: 6 | F63: 15186 | G63: 192.816 | H63: 4.78 | I63: 36.985
A64: 120 | B64: =A64 -> 120 | C64: UTM | E64: 7 | F64: 14089 | G64: 178.972 | H64: 4.846 | I64: 37.047
A65: 131 | B65: =A65 -> 131 | C65: UTM | E65: 6 | F65: 16505 | G65: 207.922 | H65: 4.807 | I65: 36.99
A66: 131 | B66: =A66 -> 131 | C66: UTM | E66: 7 | F66: 15325 | G66: 195.234 | H66: 4.794 | I66: 37.008
A67: 132 | B67: =A67 -> 132 | C67: UTM | E67: 6 | F67: 19965 | G67: 243.293 | H67: 4.862 | I67: 36.822
A68: 132 | B68: =A68 -> 132 | C68: UTM | E68: 7 | F68: 18790 | G68: 230.378 | H68: 4.797 | I68: 36.91
A69: 143 | B69: =A69 -> 143 | C69: UTM | E69: 6 | F69: 20299 | G69: 246.667 | H69: 4.808 | I69: 36.402
A70: 143 | B70: =A70 -> 143 | C70: UTM | E70: 7 | F70: 19128 | G70: 233.266 | H70: 4.779 | I70: 36.558
A71: 144 | B71: =A71 -> 144 | C71: UTM | E71: 6 | F71: 17137 | G71: 217.387 | H71: 4.804 | I71: 36.954
A72: 144 | B72: =A72 -> 144 | C72: UTM | E72: 7 | F72: 15969 | G72: 202.169 | H72: 4.838 | I72: 36.987
... A80: 168 | B80: =A80 -> 168 | C80: UTM | E80: 7 | F80: 11208 | G80: 142.459 | H80: 4.84 | I80: 37.069

Sheet Raw All
A1: Row | B1: Identifier 1 | C1: Identifier 2 | D1: Comment | E1: Peak Nr | F1: Area All | G1: Ampl 44 | H1: Ampl 45 | I1: Ampl 46 | J1: Area 44 | K1: d 13C/12C | L1: d 18O/16O | M1: Information | N1: Date | O1: Time | P1: Time Code | Q1: BGD 44 | R1: BGD 45 | S1: BGD 46
A3: 1 | B3: blank | C3: 0 | D3: 1 | E3: 1 | F3: 202.639 | G3: 10433 | H3: 12305 | I3: 14378 | J3: 199.462 | K3: -19.917 | L3: 24.418 | M3: Peak Center found at (61925);Inject Sample No 1 | N3: 04/23/25 | O3: 16:18:20 | P3: 2025/04/23 16:18:20 | Q3: 8.7 | R3: 11.0 | S3: 13.6
A4: 1 | B4: blank | C4: 0 | D4: 1 | E4: 2 | F4: 203.631 | G4: 10474 | H4: 12355 | I4: 14429 | J4: 200.438 | K4: -19.927 | L4: 24.421 | M4: Peak Center found at (61925);Inject Sample No 1 | N4: 04/23/25 | O4: 16:18:20 | P4: 2025/04/23 16:18:20 | Q4: 13.7 | R4: 16.9 | S4: 20.9
A5: 1 | B5: blank | C5: 0 | D5: 1 | E5: 3 | F5: 203.328 | G5: 10509 | H5: 12394 | I5: 14481 | J5: 200.14 | K5: -19.938 | L5: 24.421 | M5: Peak Center found at (61925);Inject Sample No 1 | N5: 04/23/25 | O5: 16:18:20 | P5: 2025/04/23 16:18:20 | Q5: 14.7 | R5: 18.1 | S5: 22.3
A6: 1 | B6: blank | C6: 0 | D6: 1 | E6: 4 | F6: 203.832 | G6: 10477 | H6: 12356 | I6: 14431 | J6: 200.636 | K6: -19.937 | L6: 24.418 | M6: Peak Center found at (61925);Inject Sample No 1 | N6: 04/23/25 | O6: 16:18:20 | P6: 2025/04/23 16:18:20 | Q6: 15.1 | R6: 18.6 | S6: 23.0
A7: 2 | B7: NBS 18 | C7: 0.23 | D7: 2 | E7: 1 | F7: 202.643 | G7: 10440 | H7: 12312 | I7: 14386 | J7: 199.466 | K7: -19.93 | L7: 24.426 | M7: Peak Center found at (61915);Inject Sample No 2 | N7: 04/23/25 | O7: 16:32:47 | P7: 2025/04/23 16:32:47 | Q7: 7.6 | R7: 9.7 | S7: 11.9
A8: 2 | B8: NBS 18 | C8: 0.23 | D8: 2 | E8: 2 | F8: 203.452 | G8: 10464 | H8: 12340 | I8: 14420 | J8: 200.262 | K8: -19.926 | L8: 24.431 | M8: Peak Center found at (61915);Inject Sample No 2 | N8: 04/23/25 | O8: 16:32:47 | P8: 2025/04/23 16:32:47 | Q8: 12.9 | R8: 15.9 | S8: 19.5
A9: 2 | B9: NBS 18 | C9: 0.23 | D9: 2 | E9: 3 | F9: 203.611 | G9: 10508 | H9: 12392 | I9: 14479 | J9: 200.419 | K9: -19.936 | L9: 24.436 | M9: Peak Center found at (61915);Inject Sample No 2 | N9: 04/23/25 | O9: 16:32:47 | P9: 2025/04/23 16:32:47 | Q9: 14.0 | R9: 17.3 | S9: 21.1
A10: 2 | B10: NBS 18 | C10: 0.23 | D10: 2 | E10: 4 | F10: 203.502 | G10: 10462 | H10: 12338 | I10: 14416 | J10: 200.311 | K10: -19.937 | L10: 24.418 | M10: Peak Center found at (61915);Inject Sample No 2 | N10: 04/23/25 | O10: 16:32:47 | P10: 2025/04/23 16:32:47 | Q10: 14.6 | R10: 17.9 | S10: 21.9
A11: 2 | B11: NBS 18 | C11: 0.23 | D11: 2 | E11: 5 | F11: 197.376 | G11: 15121 | H11: 18136 | I11: 20695 | J11: 194.255 | K11: -4.618 | L11: 16.322 | M11: Peak Center found at (61915);Inject Sample No 2 | N11: 04/23/25 | O11: 16:32:47 | P11: 2025/04/23 16:32:47 | Q11: 4.8 | R11: 6.4 | S11: 13.9
A12: 2 | B12: NBS 18 | C12: 0.23 | D12: 2 | E12: 6 | F12: 172.174 | G12: 13350 | H12: 16008 | I12: 18272 | J12: 169.452 | K12: -4.729 | L12: 17.385 | M12: Peak Center found at (61915);Inject Sample No 2 | N12: 04/23/25 | O12: 16:32:47 | P12: 2025/04/23 16:32:47 | Q12: 20.2 | R12: 24.8 | S12: 29.4
A13: 2 | B13: NBS 18 | C13: 0.23 | D13: 2 | E13: 7 | F13: 159.976 | G13: 12410 | H13: 14880 | I13: 16991 | J13: 157.446 | K13: -4.666 | L13: 17.391 | M13: Peak Center found at (61915);Inject Sample No 2 | N13: 04/23/25 | O13: 16:32:47 | P13: 2025/04/23 16:32:47 | Q13: 56.2 | R13: 67.7 | S13: 78.7
A14: 3 | B14: NBS18 | C14: 0.248 | D14: 3 | E14: 1 | F14: 202.569 | G14: 10437 | H14: 12310 | I14: 14382 | J14: 199.393 | K14: -19.927 | L14: 24.394 | M14: Peak Center found at (61925);Inject Sample No 3 | N14: 04/23/25 | O14: 16:47:13 | P14: 2025/04/23 16:47:13 | Q14: 11.7 | R14: 14.7 | S14: 17.8
... A822: 118 | B822: 12 SPL A4 Path H 69A | C822: 0.254 | D822: 118 | E822: 7 | F822: 172.567 | G822: 13419 | H822: 16155 | I822: 18709 | J822: 169.817 | K822: -1.271 | L822: 36.062 | M822: Peak Center found at (61925);Inject Sample No 22 | N822: 04/24/25 | O822: 21:20:06 | P822: 2025/04/24 21:20:06 | Q822: 61.2 | R822: 74.0 | S822: 86.3
A823: 119 | B823: UTM | D823: 119 | E823: 1 | F823: 204.742 | G823: 10484 | H823: 12365 | I823: 14444 | J823: 201.532 | K823: -19.94 | L823: 24.406 | M823: Peak Center found at (61925);Inject Sample No 23 | N823: 04/24/25 | O823: 21:33:57 | P823: 2025/04/24 21:33:57 | Q823: 14.5 | R823: 18.1 | S823: 21.2
A824: 119 | B824: UTM | D824: 119 | E824: 2 | F824: 202.402 | G824: 10482 | H824: 12362 | I824: 14442 | J824: 199.228 | K824: -19.93 | L824: 24.414 | M824: Peak Center found at (61925);Inject Sample No 23 | N824: 04/24/25 | O824: 21:33:57 | P824: 2025/04/24 21:33:57 | Q824: 18.9 | R824: 23.2 | S824: 27.5
A825: 119 | B825: UTM | D825: 119 | E825: 3 | F825: 203.766 | G825: 10519 | H825: 12408 | I825: 14498 | J825: 200.571 | K825: -19.928 | L825: 24.425 | M825: Peak Center found at (61925);Inject Sample No 23 | N825: 04/24/25 | O825: 21:33:57 | P825: 2025/04/24 21:33:57 | Q825: 19.1 | R825: 23.5 | S825: 28.0
A826: 119 | B826: UTM | D826: 119 | E826: 4 | F826: 203.732 | G826: 10494 | H826: 12378 | I826: 14458 | J826: 200.537 | K826: -19.937 | L826: 24.418 | M826: Peak Center found at (61925);Inject Sample No 23 | N826: 04/24/25 | O826: 21:33:57 | P826: 2025/04/24 21:33:57 | Q826: 19.2 | R826: 23.5 | S826: 28.0
A827: 119 | B827: UTM | D827: 119 | E827: 5 | F827: 212.841 | G827: 16490 | H827: 19994 | I827: 23003 | J827: 209.436 | K827: 4.679 | L827: 36.733 | M827: Peak Center found at (61925);Inject Sample No 23 | N827: 04/24/25 | O827: 21:33:57 | P827: 2025/04/24 21:33:57 | Q827: 5.0 | R827: 6.7 | S827: 8.2
A828: 119 | B828: UTM | D828: 119 | E828: 6 | F828: 187.746 | G828: 14949 | H828: 18123 | I828: 20858 | J828: 184.742 | K828: 4.737 | L828: 36.845 | M828: Peak Center found at (61925);Inject Sample No 23 | N828: 04/24/25 | O828: 21:33:57 | P828: 2025/04/24 21:33:57 | Q828: 22.4 | R828: 27.7 | S828: 32.3
A829: 119 | B829: UTM | D829: 119 | E829: 7 | F829: 175.457 | G829: 14087 | H829: 17072 | I829: 19653 | J829: 172.649 | K829: 4.805 | L829: 36.916 | M829: Peak Center found at (61925);Inject Sample No 23 | N829: 04/24/25 | O829: 21:33:57 | P829: 2025/04/24 21:33:57 | Q829: 62.0 | R829: 75.3 | S829: 87.3
A830: 120 | B830: UTM | D830: 120 | E830: 1 | F830: 205.665 | G830: 10508 | H830: 12394 | I830: 14476 | J830: 202.44 | K830: -19.929 | L830: 24.412 | M830: Peak Center found at (61925);Inject Sample No 24 | N830: 04/24/25 | O830: 21:47:47 | P830: 2025/04/24 21:47:47 | Q830: 15.0 | R830: 18.6 | S830: 21.9
A831: 120 | B831: UTM | D831: 120 | E831: 2 | F831: 203.085 | G831: 10520 | H831: 12408 | I831: 14494 | J831: 199.901 | K831: -19.939 | L831: 24.409 | M831: Peak Center found at (61925);Inject Sample No 24 | N831: 04/24/25 | O831: 21:47:47 | P831: 2025/04/24 21:47:47 | Q831: 19.2 | R831: 23.6 | S831: 28.0
A832: 120 | B832: UTM | D832: 120 | E832: 3 | F832: 204.518 | G832: 10562 | H832: 12457 | I832: 14554 | J832: 201.311 | K832: -19.942 | L832: 24.43 | M832: Peak Center found at (61925);Inject Sample No 24 | N832: 04/24/25 | O832: 21:47:47 | P832: 2025/04/24 21:47:47 | Q832: 19.4 | R832: 23.9 | S832: 28.3
A833: 120 | B833: UTM | D833: 120 | E833: 4 | F833: 204.551 | G833: 10526 | H833: 12415 | I833: 14502 | J833: 201.343 | K833: -19.937 | L833: 24.418 | M833: Peak Center found at (61925);Inject Sample No 24 | N833: 04/24/25 | O833: 21:47:47 | P833: 2025/04/24 21:47:47 | Q833: 19.3 | R833: 23.7 | S833: 28.3
A834: 120 | B834: UTM | D834: 120 | E834: 5 | F834: 224.486 | G834: 17178 | H834: 20808 | I834: 23964 | J834: 220.894 | K834: 4.796 | L834: 36.797 | M834: Peak Center found at (61925);Inject Sample No 24 | N834: 04/24/25 | O834: 21:47:47 | P834: 2025/04/24 21:47:47 | Q834: 5.4 | R834: 7.2 | S834: 9.3
... A836: 120 | B836: UTM | D836: 120 | E836: 7 | F836: 181.883 | G836: 14089 | H836: 17061 | I836: 19661 | J836: 178.972 | K836: 4.846 | L836: 37.047 | M836: Peak Center found at (61925);Inject Sample No 24 | N836: 04/24/25 | O836: 21:47:47 | P836: 2025/04/24 21:47:47 | Q836: 63.0 | R836: 76.5 | S836: 88.8
A837: 121 | B837: 12 SPL A4 Path H 70A | C837: 0.242 | D837: 121 | E837: 1 | F837: 204.852 | G837: 10476 | H837: 12356 | I837: 14433 | J837: 201.64 | K837: -19.951 | L837: 24.422 | M837: Peak Center found at (61925);Inject Sample No 25 | N837: 04/24/25 | O837: 22:01:38 | P837: 2025/04/24 22:01:38 | Q837: 14.7 | R837: 18.3 | S837: 21.6
A838: 121 | B838: 12 SPL A4 Path H 70A | C838: 0.242 | D838: 121 | E838: 2 | F838: 202.487 | G838: 10479 | H838: 12360 | I838: 14437 | J838: 199.312 | K838: -19.951 | L838: 24.423 | M838: Peak Center found at (61925);Inject Sample No 25 | N838: 04/24/25 | O838: 22:01:38 | P838: 2025/04/24 22:01:38 | Q838: 19.0 | R838: 23.4 | S838: 27.7
A839: 121 | B839: 12 SPL A4 Path H 70A | C839: 0.242 | D839: 121 | E839: 3 | F839: 203.806 | G839: 10523 | H839: 12412 | I839: 14502 | J839: 200.61 | K839: -19.966 | L839: 24.435 | M839: Peak Center found at (61925);Inject Sample No 25 | N839: 04/24/25 | O839: 22:01:38 | P839: 2025/04/24 22:01:38 | Q839: 19.2 | R839: 23.7 | S839: 28.0
A840: 121 | B840: 12 SPL A4 Path H 70A | C840: 0.242 | D840: 121 | E840: 4 | F840: 203.599 | G840: 10481 | H840: 12361 | I840: 14439 | J840: 200.406 | K840: -19.937 | L840: 24.418 | M840: Peak Center found at (61925);Inject Sample No 25 | N840: 04/24/25 | O840: 22:01:38 | P840: 2025/04/24 22:01:38 | Q840: 19.2 | R840: 23.6 | S840: 28.0
A841: 121 | B841: 12 SPL A4 Path H 70A | C841: 0.242 | D841: 121 | E841: 5 | F841: 199.329 | G841: 15660 | H841: 18876 | I841: 21821 | J841: 196.154 | K841: -1.531 | L841: 35.8 | M841: Peak Center found at (61925);Inject Sample No 25 | N841: 04/24/25 | O841: 22:01:38 | P841: 2025/04/24 22:01:38 | Q841: 5.0 | R841: 6.7 | S841: 8.1
A842: 121 | B842: 12 SPL A4 Path H 70A | C842: 0.242 | D842: 121 | E842: 6 | F842: 177.249 | G842: 14255 | H842: 17178 | I842: 19866 | J842: 174.426 | K842: -1.532 | L842: 35.9 | M842: Peak Center found at (61925);Inject Sample No 25 | N842: 04/24/25 | O842: 22:01:38 | P842: 2025/04/24 22:01:38 | Q842: 21.9 | R842: 27.0 | S842: 31.5
A843: 121 | B843: 12 SPL A4 Path H 70A | C843: 0.242 | D843: 121 | E843: 7 | F843: 165.857 | G843: 13433 | H843: 16185 | I843: 18720 | J843: 163.215 | K843: -1.455 | L843: 35.913 | M843: Peak Center found at (61925);Inject Sample No 25 | N843: 04/24/25 | O843: 22:01:38 | P843: 2025/04/24 22:01:38 | Q843: 60.3 | R843: 72.9 | S843: 85.1
A844: 122 | B844: 12 SPL A4 Path H 71A | C844: 0.232 | D844: 122 | E844: 1 | F844: 205.026 | G844: 10494 | H844: 12377 | I844: 14450 | J844: 201.811 | K844: -19.925 | L844: 24.407 | M844: Peak Center found at (61935);Inject Sample No 26 | N844: 04/24/25 | O844: 22:15:29 | P844: 2025/04/24 22:15:29 | Q844: 14.7 | R844: 18.2 | S844: 21.5
A845: 122 | B845: 12 SPL A4 Path H 71A | C845: 0.232 | D845: 122 | E845: 2 | F845: 202.846 | G845: 10494 | H845: 12377 | I845: 14449 | J845: 199.666 | K845: -19.942 | L845: 24.41 | M845: Peak Center found at (61935);Inject Sample No 26 | N845: 04/24/25 | O845: 22:15:29 | P845: 2025/04/24 22:15:29 | Q845: 18.9 | R845: 23.3 | S845: 27.5
A846: 122 | B846: 12 SPL A4 Path H 71A | C846: 0.232 | D846: 122 | E846: 3 | F846: 204.165 | G846: 10539 | H846: 12431 | I846: 14513 | J846: 200.964 | K846: -19.945 | L846: 24.422 | M846: Peak Center found at (61935);Inject Sample No 26 | N846: 04/24/25 | O846: 22:15:29 | P846: 2025/04/24 22:15:29 | Q846: 19.2 | R846: 23.6 | S846: 28.0
A847: 122 | B847: 12 SPL A4 Path H 71A | C847: 0.232 | D847: 122 | E847: 4 | F847: 204.212 | G847: 10506 | H847: 12392 | I847: 14466 | J847: 201.01 | K847: -19.937 | L847: 24.418 | M847: Peak Center found at (61935);Inject Sample No 26 | N847: 04/24/25 | O847: 22:15:29 | P847: 2025/04/24 22:15:29 | Q847: 19.2 | R847: 23.5 | S847: 28.0
A848: 122 | B848: 12 SPL A4 Path H 71A | C848: 0.232 | D848: 122 | E848: 5 | F848: 203.62 | G848: 15441 | H848: 18588 | I848: 21497 | J848: 200.377 | K848: -1.697 | L848: 35.459 | M848: Peak Center found at (61935);Inject Sample No 26 | N848: 04/24/25 | O848: 22:15:29 | P848: 2025/04/24 22:15:29 | Q848: 5.7 | R848: 7.6 | S848: 10.1
... A906: 130 | B906: 12 SPL A4 Path H 79A | C906: 0.238 | D906: 130 | E906: 7 | F906: 153.774 | G906: 12152 | H906: 14629 | I906: 16938 | J906: 151.325 | K906: -1.885 | L906: 35.793 | M906: Peak Center found at (61925);Inject Sample No 34 | N906: 04/25/25 | O906: 00:06:17 | P906: 2025/04/25 00:06:17 | Q906: 55.4 | R906: 67.0 | S906: 78.3
...
