Workbook
Name gasbenchCO2template.wke: #REF!

Sheet FINAL REPORTED
A1: Run | B1: Identifier 1 | C1: Mass (mg) | D1: Amp 44 | E1: Area 44 | F1: δ13C (PDB) | G1: δ18O (SMOW)
A2: 13 | B2: A- 1A | C2: 0.244 | D2: 13165 | E2: 160.521 | F2: -2.6963176 | G2: 25.440647
A3: 14 | B3: A- 2A | C3: 0.248 | D3: 14161 | E3: 175.798 | F3: -2.3114515 | G3: 25.275009
A4: 15 | B4: A- 3A | C4: 0.276 | D4: 14122 | E4: 169.817 | F4: -2.0294437 | G4: 25.172705
A5: 16 | B5: A- 4A | C5: 0.218 | D5: 9853 | E5: 122.736 | F5: -2.232599 | G5: 25.295882
A6: 17 | B6: A- 5A | C6: 0.278 | D6: 13918 | E6: 165.69 | F6: -2.699883 | G6: 25.309683
A7: 18 | B7: A- 6A | C7: 0.342 | D7: 16023 | E7: 197.922 | F7: -3.1309658 | G7: 25.334855
A8: 19 | B8: A- 7A | C8: 0.328 | D8: 16894 | E8: 199.095 | F8: -3.2271782 | G8: 25.485706
A9: 20 | B9: A- 8A | C9: 0.218 | D9: 8817 | E9: 109.331 | F9: -2.8911769 | G9: 25.389915
A10: 21 | B10: A- 9A | C10: 0.258 | D10: 12579 | E10: 150.47 | F10: -2.9792192 | G10: 25.278091
A11: 22 | B11: A- 10A | C11: 0.344 | D11: 16356 | E11: 201.07 | F11: -2.7922402 | G11: 25.213369
A12: 25 | B12: A- 11A | C12: 0.362 | D12: 15280 | E12: 189.669 | F12: -3.0708742 | G12: 25.189516
A13: 26 | B13: A- 12A | C13: 0.218 | D13: 9433 | E13: 114.142 | F13: -3.1451404 | G13: 25.173815
... A52: 73 | B52: B- 19A | C52: 0.218 | D52: 12388 | E52: 149.555 | F52: -3.52844 | G52: 25.484444
B53: B-20A | C53: Must not have been acidified, no CO2 peak, will rerun
A54: 75 | B54: B- 21A | C54: 0.366 | D54: 20009 | E54: 237.331 | F54: -2.553186 | G54: 25.475803
A55: 76 | B55: B- 22A | C55: 0.252 | D55: 15783 | E55: 195.195 | F55: -2.2442949 | G55: 25.30641
A56: 77 | B56: B- 23A | C56: 0.322 | D56: 18318 | E56: 217.082 | F56: -2.3496208 | G56: 25.158661
A57: 78 | B57: B- 24A | C57: 0.256 | D57: 13262 | E57: 163.82 | F57: -2.4870914 | G57: 24.781936
A58: 79 | B58: B- 25A | C58: 0.258 | D58: 13946 | E58: 168.943 | F58: -2.3771001 | G58: 25.036815
A59: 80 | B59: B- 26A | C59: 0.27 | D59: 14698 | E59: 179.91 | F59: -2.8721433 | G59: 25.034847
A60: 81 | B60: B- 27A | C60: 0.306 | D60: 18489 | E60: 226.002 | F60: -3.2172649 | G60: 25.524888
A61: 82 | B61: B- 28A | C61: 0.192 | D61: 10714 | E61: 130.06 | F61: -2.6838394 | G61: 25.279932
A62: 85 | B62: B- 29A | C62: 0.248 | D62: 12372 | E62: 153.409 | F62: -2.4605429 | G62: 25.72815
A63: 86 | B63: C- 1A | C63: 0.28 | D63: 15683 | E63: 186.473 | F63: -1.9497485 | G63: 25.532837
A64: 87 | B64: C- 2A | C64: 0.236 | D64: 12712 | E64: 157.025 | F64: -1.6949637 | G64: 25.644608
A65: 88 | B65: C- 3A | C65: 0.19 | D65: 11079 | E65: 131.652 | F65: -1.8716342 | G65: 25.646969
... A75: 117 | B75: C- 13A | C75: 0.268 | D75: 14613 | E75: 163.044 | F75: -1.6709233 | G75: 25.445388
A76: 118 | B76: C- 14A | C76: 0.234 | D76: 11144 | E76: 120.269 | F76: -0.088895134 | G76: 24.622614 | I76: Septa cap did not close correctly, air got into vial
A77: 119 | B77: C- 15A | C77: 0.322 | D77: 16405 | E77: 187.482 | F77: -1.975695 | G77: 25.415451
A78: 120 | B78: C- 16A | C78: 0.326 | D78: 17036 | E78: 193.322 | F78: -2.3241026 | G78: 25.188085
A79: 121 | B79: C- 17A | C79: 0.21 | D79: 10071 | E79: 118.336 | F79: -2.0182553 | G79: 25.629035
A80: 122 | B80: C- 18A | C80: 0.336 | D80: 18920 | E80: 211.937 | F80: -1.6790227 | G80: 25.532244
A81: 123 | B81: C- 19A | C81: 0.228 | D81: 12497 | E81: 146.596 | F81: -1.7924719 | G81: 25.096108
A82: 126 | B82: C- 20A | C82: 0.324 | D82: 17334 | E82: 193.896 | F82: -2.1289449 | G82: 25.16814
A83: 127 | B83: C- 21A | C83: 0.314 | D83: 15922 | E83: 185.073 | F83: -1.8331192 | G83: 25.129081
A84: 128 | B84: C- 22A | C84: 0.296 | D84: 17810 | E84: 199.731 | F84: -2.3940079 | G84: 25.321545
A85: 129 | B85: C- 23A | C85: 0.302 | D85: 13684 | E85: 158.749 | F85: -2.6281214 | G85: 25.528007
A86: 130 | B86: C- 24A | C86: 0.28 | D86: 15718 | E86: 179.005 | F86: -1.8438699 | G86: 25.625131
A87: 131 | B87: D- 1A | C87: 0.198 | D87: 15709 | E87: 181.169 | F87: -1.4168044 | G87: 25.506441
...

Sheet 3-Format-Final
A1: Row | B1: Identifier 1 | C1: Identifier 2 | D1: Ampl 44 | E1: Area 44 | F1: δ13C (PDB) | G1: δ18O (SMOW)
A3: 13 | B3: A- 1A | C3: 0.244 | D3: 13165 | E3: 160.521 | F3: -2.6963176 | G3: 25.440647
A4: 14 | B4: A- 2A | C4: 0.248 | D4: 14161 | E4: 175.798 | F4: -2.3114515 | G4: 25.275009
A5: 15 | B5: A- 3A | C5: 0.276 | D5: 14122 | E5: 169.817 | F5: -2.0294437 | G5: 25.172705
A6: 16 | B6: A- 4A | C6: 0.218 | D6: 9853 | E6: 122.736 | F6: -2.232599 | G6: 25.295882
A7: 17 | B7: A- 5A | C7: 0.278 | D7: 13918 | E7: 165.69 | F7: -2.699883 | G7: 25.309683
A8: 18 | B8: A- 6A | C8: 0.342 | D8: 16023 | E8: 197.922 | F8: -3.1309658 | G8: 25.334855
A9: 19 | B9: A- 7A | C9: 0.328 | D9: 16894 | E9: 199.095 | F9: -3.2271782 | G9: 25.485706
A10: 20 | B10: A- 8A | C10: 0.218 | D10: 8817 | E10: 109.331 | F10: -2.8911769 | G10: 25.389915
A11: 21 | B11: A- 9A | C11: 0.258 | D11: 12579 | E11: 150.47 | F11: -2.9792192 | G11: 25.278091
A12: 22 | B12: A- 10A | C12: 0.344 | D12: 16356 | E12: 201.07 | F12: -2.7922402 | G12: 25.213369
A13: 25 | B13: A- 11A | C13: 0.362 | D13: 15280 | E13: 189.669 | F13: -3.0708742 | G13: 25.189516
A14: 26 | B14: A- 12A | C14: 0.218 | D14: 9433 | E14: 114.142 | F14: -3.1451404 | G14: 25.173815
... A196: 197 | B196: UTM 33 | C196: 0.25 | D196: 13031 | E196: 147.99 | F196: 4.5192674 | G196: 26.598502

Sheet RAW_Corrected
A1: Row | B1: Identifier 1 | C1: Identifier 2 | D1: Peak Nr | E1: Ampl 44 | F1: Area 44 | G1: d 13C/12C | H1: d 18O/16O | J1: d 13C/12C ave | K1: stnd dev | M1: Ave ampl 44 | N1: std dev amp 44 | P1: d 18O/16O ave | Q1: stnd dev | S1: d 13C/12C drift Corr | T1: d 13C/12C amp 44 Corr | W1: d 18O/16O Drift Corr | X1: d 18O/16O Amp 44 Corr | Z1: δ13C (PDB) | AA1: δ18O (SMOW)
A3: 2 | B3: NBS18 1 | C3: 0.28 | D3: 6 | E3: 11410 | F3: 141.343 | G3: -5.456 | H3: 5.806
A4: 2 | B4: NBS18 1 | C4: 0.28 | D4: 7 | E4: 10693 | F4: 131.629 | G4: -5.421 | H4: 5.793 | J4: =AVERAGE(G3:G4) -> -5.4385 | K4: =STDEV(G3:G4) -> 0.024748737 | M4: =AVERAGE(E3:E4) -> 11051.5 | N4: =STDEV(E3:E4) -> 506.99556 | P4: =AVERAGE(H3:H4) -> 5.7995 | Q4: =STDEV(H3:H4) -> 0.0091923882 | S4: =J4-(A4-Standards!$A$121)*Standards!$AA$4 -> -5.5106086 | T4: =S4-(M4-Standards!$N$121)*Standards!$AA$55 -> -5.4817301 | W4: =P4-(A4-Standards!$A$121)*Standards!$AL$5 -> 5.6995652 | X4: =W4-(M4-Standards!$N$121)*Standards!$AL$54 -> 5.6303772 | Z4: =(T4*Standards!$O$156)+Standards!$O$157 -> -5.0098514 | AA4: =(X4*Standards!$T$156)+Standards!$T$157 -> 7.1014577
A5: 3 | B5: NBS18 2 | C5: 0.31 | D5: 6 | E5: 15181 | F5: 185.808 | G5: -5.448 | H5: 5.796
A6: 3 | B6: NBS18 2 | C6: 0.31 | D6: 7 | E6: 14111 | F6: 173.148 | G6: -5.407 | H6: 5.81 | J6: =AVERAGE(G5:G6) -> -5.4275 | K6: =STDEV(G5:G6) -> 0.028991378 | M6: =AVERAGE(E5:E6) -> 14646 | N6: =STDEV(E5:E6) -> 756.60426 | P6: =AVERAGE(H5:H6) -> 5.803 | Q6: =STDEV(H5:H6) -> 0.0098994949 | S6: =J6-(A6-Standards!$A$121)*Standards!$AA$4 -> -5.4988856 | T6: =S6-(M6-Standards!$N$121)*Standards!$AA$55 -> -5.5045143 | W6: =P6-(A6-Standards!$A$121)*Standards!$AL$5 -> 5.7040672 | X6: =W6-(M6-Standards!$N$121)*Standards!$AL$54 -> 5.7175527 | Z6: =(T6*Standards!$O$156)+Standards!$O$157 -> -5.0327783 | AA6: =(X6*Standards!$T$156)+Standards!$T$157 -> 7.1881601
A7: 4 | B7: NBS18 3 | C7: 0.33 | D7: 6 | E7: 16135 | F7: 193.207 | G7: -5.387 | H7: 5.793 | W7: .
A8: 4 | B8: NBS18 3 | C8: 0.33 | D8: 7 | E8: 15229 | F8: 181.079 | G8: -5.304 | H8: 5.794 | J8: =AVERAGE(G7:G8) -> -5.3455 | K8: =STDEV(G7:G8) -> 0.058689863 | M8: =AVERAGE(E7:E8) -> 15682 | N8: =STDEV(E7:E8) -> 640.63874 | P8: =AVERAGE(H7:H8) -> 5.7935 | Q8: =STDEV(H7:H8) -> 0.00070710678 | S8: =J8-(A8-Standards!$A$121)*Standards!$AA$4 -> -5.4161626 | T8: =S8-(M8-Standards!$N$121)*Standards!$AA$55 -> -5.4317369 | W8: =P8-(A8-Standards!$A$121)*Standards!$AL$5 -> 5.6955692 | X8: =W8-(M8-Standards!$N$121)*Standards!$AL$54 -> 5.7328827 | Z8: =(T8*Standards!$O$156)+Standards!$O$157 -> -4.9595453 | AA8: =(X8*Standards!$T$156)+Standards!$T$157 -> 7.2034069
A9: 5 | B9: NBS18 4 | C9: 0.298 | D9: 6 | E9: 13008 | F9: 161.985 | G9: -5.437 | H9: 6.039
A10: 5 | B10: NBS18 4 | C10: 0.298 | D10: 7 | E10: 12164 | F10: 150.963 | G10: -5.4 | H10: 6.056 | J10: =AVERAGE(G9:G10) -> -5.4185 | K10: =STDEV(G9:G10) -> 0.026162951 | M10: =AVERAGE(E9:E10) -> 12586 | N10: =STDEV(E9:E10) -> 596.79812 | P10: =AVERAGE(H9:H10) -> 6.0475 | Q10: =STDEV(H9:H10) -> 0.012020815 | S10: =J10-(A10-Standards!$A$121)*Standards!$AA$4 -> -5.4884396 | T10: =S10-(M10-Standards!$N$121)*Standards!$AA$55 -> -5.4742923 | W10: =P10-(A10-Standards!$A$121)*Standards!$AL$5 -> 5.9505712 | X10: =W10-(M10-Standards!$N$121)*Standards!$AL$54 -> 5.9166767 | Z10: =(T10*Standards!$O$156)+Standards!$O$157 -> -5.0023671 | AA10: =(X10*Standards!$T$156)+Standards!$T$157 -> 7.3862033
A11: 6 | B11: NBS19 1 | C11: 0.226 | D11: 6 | E11: 11298 | F11: 135.063 | G11: 1.441 | H11: 27.339
A12: 6 | B12: NBS19 1 | C12: 0.226 | D12: 7 | E12: 10678 | F12: 126.699 | G12: 1.503 | H12: 27.383 | J12: =AVERAGE(G11:G12) -> 1.472 | K12: =STDEV(G11:G12) -> 0.04384062 | M12: =AVERAGE(E11:E12) -> 10988 | N12: =STDEV(E11:E12) -> 438.4062 | P12: =AVERAGE(H11:H12) -> 27.361 | Q12: =STDEV(H11:H12) -> 0.031112698 | S12: =J12-(A12-Standards!$A$121)*Standards!$AA$4 -> 1.4027834 | T12: =S12-(M12-Standards!$N$121)*Standards!$AA$55 -> 1.4322715 | W12: =P12-(A12-Standards!$A$121)*Standards!$AL$5 -> 27.265073 | X12: =W12-(M12-Standards!$N$121)*Standards!$AL$54 -> 27.194425 | Z12: =(T12*Standards!$O$156)+Standards!$O$157 -> 1.9474323 | AA12: =(X12*Standards!$T$156)+Standards!$T$157 -> 28.548465
A13: 7 | B13: NBS19 2 | C13: 0.206 | D13: 6 | E13: 10691 | F13: 133.483 | G13: 1.48 | H13: 27.395
A14: 7 | B14: NBS19 2 | C14: 0.206 | D14: 7 | E14: 9990 | F14: 124.348 | G14: 1.55 | H14: 27.417 | J14: =AVERAGE(G13:G14) -> 1.515 | K14: =STDEV(G13:G14) -> 0.049497475 | M14: =AVERAGE(E13:E14) -> 10340.5 | N14: =STDEV(E13:E14) -> 495.68185 | P14: =AVERAGE(H13:H14) -> 27.406 | Q14: =STDEV(H13:H14) -> 0.015556349 | S14: =J14-(A14-Standards!$A$121)*Standards!$AA$4 -> 1.4465064 | T14: =S14-(M14-Standards!$N$121)*Standards!$AA$55 -> 1.4822105 | W14: =P14-(A14-Standards!$A$121)*Standards!$AL$5 -> 27.311075 | X14: =W14-(M14-Standards!$N$121)*Standards!$AL$54 -> 27.225534 | Z14: =(T14*Standards!$O$156)+Standards!$O$157 -> 1.9976839 | AA14: =(X14*Standards!$T$156)+Standards!$T$157 -> 28.579406
A15: 8 | B15: NBS19 3 | C15: 0.252 | D15: 6 | E15: 14933 | F15: 176.764 | G15: 1.485 | H15: 27.305
A16: 8 | B16: NBS19 3 | C16: 0.252 | D16: 7 | E16: 14076 | F16: 166.077 | G16: 1.541 | H16: 27.362 | J16: =AVERAGE(G15:G16) -> 1.513 | K16: =STDEV(G15:G16) -> 0.03959798 | M16: =AVERAGE(E15:E16) -> 14504.5 | N16: =STDEV(E15:E16) -> 605.99051 | P16: =AVERAGE(H15:H16) -> 27.3335 | Q16: =STDEV(H15:H16) -> 0.040305087 | S16: =J16-(A16-Standards!$A$121)*Standards!$AA$4 -> 1.4452294 | T16: =S16-(M16-Standards!$N$121)*Standards!$AA$55 -> 1.4409591 | W16: =P16-(A16-Standards!$A$121)*Standards!$AL$5 -> 27.239577 | X16: =W16-(M16-Standards!$N$121)*Standards!$AL$54 -> 27.249808 | Z16: =(T16*Standards!$O$156)+Standards!$O$157 -> 1.9561743 | AA16: =(X16*Standards!$T$156)+Standards!$T$157 -> 28.603548
A17: 9 | B17: NBS19 4 | C17: 0.28 | D17: 6 | E17: 15233 | F17: 189.197 | G17: 1.515 | H17: 27.309
A18: 9 | B18: NBS19 4 | C18: 0.28 | D18: 7 | E18: 14202 | F18: 175.852 | G18: 1.549 | H18: 27.322 | J18: =AVERAGE(G17:G18) -> 1.532 | K18: =STDEV(G17:G18) -> 0.024041631 | M18: =AVERAGE(E17:E18) -> 14717.5 | N18: =STDEV(E17:E18) -> 729.02709 | P18: =AVERAGE(H17:H18) -> 27.3155 | Q18: =STDEV(H17:H18) -> 0.0091923882 | S18: =J18-(A18-Standards!$A$121)*Standards!$AA$4 -> 1.4649524 | T18: =S18-(M18-Standards!$N$121)*Standards!$AA$55 -> 1.4586373 | W18: =P18-(A18-Standards!$A$121)*Standards!$AL$5 -> 27.222579 | X18: =W18-(M18-Standards!$N$121)*Standards!$AL$54 -> 27.237709 | Z18: =(T18*Standards!$O$156)+Standards!$O$157 -> 1.9739632 | AA18: =(X18*Standards!$T$156)+Standards!$T$157 -> 28.591515
A19: 10 | B19: UTM 1 | C19: 0.304 | D19: 6 | E19: 17381 | F19: 204.719 | G19: 3.995 | H19: 25.23
A20: 10 | B20: UTM 1 | C20: 0.304 | D20: 7 | E20: 16218 | F20: 192.9 | G20: 3.963 | H20: 25.281 | J20: =AVERAGE(G19:G20) -> 3.979 | K20: =STDEV(G19:G20) -> 0.022627417 | M20: =AVERAGE(E19:E20) -> 16799.5 | N20: =STDEV(E19:E20) -> 822.36519 | P20: =AVERAGE(H19:H20) -> 25.2555 | Q20: =STDEV(H19:H20) -> 0.036062446 | S20: =J20-(A20-Standards!$A$121)*Standards!$AA$4 -> 3.9126754 | T20: =S20-(M20-Standards!$N$121)*Standards!$AA$55 -> 3.8863731 | W20: =P20-(A20-Standards!$A$121)*Standards!$AL$5 -> 25.163581 | X20: =W20-(M20-Standards!$N$121)*Standards!$AL$54 -> 25.226597 | Z20: =(T20*Standards!$O$156)+Standards!$O$157 -> 4.4168968 | AA20: =(X20*Standards!$T$156)+Standards!$T$157 -> 26.591318
A21: 11 | B21: UTM 2 | C21: 0.244 | D21: 6 | E21: 13560 | F21: 168.174 | G21: 3.968 | H21: 25.234
A22: 11 | B22: UTM 2 | C22: 0.244 | D22: 7 | E22: 12651 | F22: 156.365 | G22: 4.003 | H22: 25.281 | J22: =AVERAGE(G21:G22) -> 3.9855 | K22: =STDEV(G21:G22) -> 0.024748737 | M22: =AVERAGE(E21:E22) -> 13105.5 | N22: =STDEV(E21:E22) -> 642.76006 | P22: =AVERAGE(H21:H22) -> 25.2575 | Q22: =STDEV(H21:H22) -> 0.033234019 | S22: =J22-(A22-Standards!$A$121)*Standards!$AA$4 -> 3.9198984 | T22: =S22-(M22-Standards!$N$121)*Standards!$AA$55 -> 3.9290585 | W22: =P22-(A22-Standards!$A$121)*Standards!$AL$5 -> 25.166583 | X22: =W22-(M22-Standards!$N$121)*Standards!$AL$54 -> 25.144637 | Z22: =(T22*Standards!$O$156)+Standards!$O$157 -> 4.4598494 | AA22: =(X22*Standards!$T$156)+Standards!$T$157 -> 26.509803
A23: 12 | B23: UTM 3 | C23: 0.236 | D23: 6 | E23: 13750 | F23: 166.668 | G23: 3.986 | H23: 25.228
A24: 12 | B24: UTM 3 | C24: 0.236 | D24: 7 | E24: 12748 | F24: 154.93 | G24: 4.027 | H24: 25.286 | J24: =AVERAGE(G23:G24) -> 4.0065 | K24: =STDEV(G23:G24) -> 0.028991378 | M24: =AVERAGE(E23:E24) -> 13249 | N24: =STDEV(E23:E24) -> 708.52099 | P24: =AVERAGE(H23:H24) -> 25.257 | Q24: =STDEV(H23:H24) -> 0.041012193 | S24: =J24-(A24-Standards!$A$121)*Standards!$AA$4 -> 3.9416214 | T24: =S24-(M24-Standards!$N$121)*Standards!$AA$55 -> 3.9494039 | W24: =P24-(A24-Standards!$A$121)*Standards!$AL$5 -> 25.167085 | X24: =W24-(M24-Standards!$N$121)*Standards!$AL$54 -> 25.14844 | Z24: =(T24*Standards!$O$156)+Standards!$O$157 -> 4.4803221 | AA24: =(X24*Standards!$T$156)+Standards!$T$157 -> 26.513585
A25: 13 | B25: A- 1A | C25: 0.244 | D25: 6 | E25: 14003 | F25: 172.189 | G25: -3.133 | H25: 24.157
A26: 13 | B26: A- 1A | C26: 0.244 | D26: 7 | E26: 13165 | F26: 160.521 | G26: -3.113 | H26: 24.182 | J26: =AVERAGE(G25:G26) -> -3.123 | K26: =STDEV(G25:G26) -> 0.014142136 | M26: =AVERAGE(E25:E26) -> 13584 | N26: =STDEV(E25:E26) -> 592.55548 | P26: =AVERAGE(H25:H26) -> 24.1695 | Q26: =STDEV(H25:H26) -> 0.01767767 | S26: =J26-(A26-Standards!$A$121)*Standards!$AA$4 -> -3.1871556 | T26: =S26-(M26-Standards!$N$121)*Standards!$AA$55 -> -3.1825891 | W26: =P26-(A26-Standards!$A$121)*Standards!$AL$5 -> 24.080587 | X26: =W26-(M26-Standards!$N$121)*Standards!$AL$54 -> 24.069647 | Z26: =(T26*Standards!$O$156)+Standards!$O$157 -> -2.6963176 | AA26: =(X26*Standards!$T$156)+Standards!$T$157 -> 25.440647
A27: 14 | B27: A- 2A | C27: 0.248 | D27: 6 | E27: 15351 | F27: 190.063 | G27: -2.752 | H27: 23.946
A28: 14 | B28: A- 2A | C28: 0.248 | D28: 7 | E28: 14161 | F28: 175.798 | G28: -2.708 | H28: 24.004 | J28: =AVERAGE(G27:G28) -> -2.73 | K28: =STDEV(G27:G28) -> 0.031112698 | M28: =AVERAGE(E27:E28) -> 14756 | N28: =STDEV(E27:E28) -> 841.45707 | P28: =AVERAGE(H27:H28) -> 23.975 | Q28: =STDEV(H27:H28) -> 0.041012193 | S28: =J28-(A28-Standards!$A$121)*Standards!$AA$4 -> -2.7934326 | T28: =S28-(M28-Standards!$N$121)*Standards!$AA$55 -> -2.8001173 | W28: =P28-(A28-Standards!$A$121)*Standards!$AL$5 -> 23.887089 | X28: =W28-(M28-Standards!$N$121)*Standards!$AL$54 -> 23.903105 | Z28: =(T28*Standards!$O$156)+Standards!$O$157 -> -2.3114515 | AA28: =(X28*Standards!$T$156)+Standards!$T$157 -> 25.275009
A29: 15 | B29: A- 3A | C29: 0.276 | D29: 6 | E29: 14967 | F29: 181.75 | G29: -2.459 | H29: 23.862
A30: 15 | B30: A- 3A | C30: 0.276 | D30: 7 | E30: 14122 | F30: 169.817 | G30: -2.446 | H30: 23.89 | J30: =AVERAGE(G29:G30) -> -2.4525 | K30: =STDEV(G29:G30) -> 0.0091923882 | M30: =AVERAGE(E29:E30) -> 14544.5 | N30: =STDEV(E29:E30) -> 597.50523 | P30: =AVERAGE(H29:H30) -> 23.876 | Q30: =STDEV(H29:H30) -> 0.01979899 | S30: =J30-(A30-Standards!$A$121)*Standards!$AA$4 -> -2.5152096 | T30: =S30-(M30-Standards!$N$121)*Standards!$AA$55 -> -2.5198639 | W30: =P30-(A30-Standards!$A$121)*Standards!$AL$5 -> 23.789091 | X30: =W30-(M30-Standards!$N$121)*Standards!$AL$54 -> 23.800242 | Z30: =(T30*Standards!$O$156)+Standards!$O$157 -> -2.0294437 | AA30: =(X30*Standards!$T$156)+Standards!$T$157 -> 25.172705
A31: 16 | B31: A- 4A | C31: 0.218 | D31: 6 | E31: 10614 | F31: 132.22 | G31: -2.733 | H31: 24.075
A32: 16 | B32: A- 4A | C32: 0.218 | D32: 7 | E32: 9853 | F32: 122.736 | G32: -2.66 | H32: 24.121 | J32: =AVERAGE(G31:G32) -> -2.6965 | K32: =STDEV(G31:G32) -> 0.051618795 | M32: =AVERAGE(E31:E32) -> 10233.5 | N32: =STDEV(E31:E32) -> 538.10826 | P32: =AVERAGE(H31:H32) -> 24.098 | Q32: =STDEV(H31:H32) -> 0.032526912 | S32: =J32-(A32-Standards!$A$121)*Standards!$AA$4 -> -2.7584866 | T32: =S32-(M32-Standards!$N$121)*Standards!$AA$55 -> -2.7217553 | W32: =P32-(A32-Standards!$A$121)*Standards!$AL$5 -> 24.012093 | X32: =W32-(M32-Standards!$N$121)*Standards!$AL$54 -> 23.924091 | Z32: =(T32*Standards!$O$156)+Standards!$O$157 -> -2.232599 | AA32: =(X32*Standards!$T$156)+Standards!$T$157 -> 25.295882
A33: 17 | B33: A- 5A | C33: 0.278 | D33: 6 | E33: 14799 | F33: 176.81 | G33: -3.134 | H33: 23.986
A34: 17 | B34: A- 5A | C34: 0.278 | D34: 7 | E34: 13918 | F34: 165.69 | G34: -3.11 | H34: 24.046 | J34: =AVERAGE(G33:G34) -> -3.122 | K34: =STDEV(G33:G34) -> 0.016970563 | M34: =AVERAGE(E33:E34) -> 14358.5 | N34: =STDEV(E33:E34) -> 622.96107 | P34: =AVERAGE(H33:H34) -> 24.016 | Q34: =STDEV(H33:H34) -> 0.042426407 | S34: =J34-(A34-Standards!$A$121)*Standards!$AA$4 -> -3.1832636 | T34: =S34-(M34-Standards!$N$121)*Standards!$AA$55 -> -3.1861323 | W34: =P34-(A34-Standards!$A$121)*Standards!$AL$5 -> 23.931095 | X34: =W34-(M34-Standards!$N$121)*Standards!$AL$54 -> 23.937968 | Z34: =(T34*Standards!$O$156)+Standards!$O$157 -> -2.699883 | AA34: =(X34*Standards!$T$156)+Standards!$T$157 -> 25.309683
A35: 18 | B35: A- 6A | C35: 0.342 | D35: 6 | E35: 17199 | F35: 212.902 | G35: -3.545 | H35: 23.99
A36: 18 | B36: A- 6A | C36: 0.342 | D36: 7 | E36: 16023 | F36: 197.922 | G36: -3.514 | H36: 23.987 | J36: =AVERAGE(G35:G36) -> -3.5295 | K36: =STDEV(G35:G36) -> 0.02192031 | M36: =AVERAGE(E35:E36) -> 16611 | N36: =STDEV(E35:E36) -> 831.55757 | P36: =AVERAGE(H35:H36) -> 23.9885 | Q36: =STDEV(H35:H36) -> 0.0021213203 | S36: =J36-(A36-Standards!$A$121)*Standards!$AA$4 -> -3.5900406 | T36: =S36-(M36-Standards!$N$121)*Standards!$AA$55 -> -3.6145333 | W36: =P36-(A36-Standards!$A$121)*Standards!$AL$5 -> 23.904597 | X36: =W36-(M36-Standards!$N$121)*Standards!$AL$54 -> 23.963278 | Z36: =(T36*Standards!$O$156)+Standards!$O$157 -> -3.1309658 | AA36: =(X36*Standards!$T$156)+Standards!$T$157 -> 25.334855
A37: 19 | B37: A- 7A | C37: 0.328 | D37: 6 | E37: 18169 | F37: 213.95 | G37: -3.629 | H37: 24.109
A38: 19 | B38: A- 7A | C38: 0.328 | D38: 7 | E38: 16894 | F38: 199.095 | G38: -3.605 | H38: 24.127 | J38: =AVERAGE(G37:G38) -> -3.617 | K38: =STDEV(G37:G38) -> 0.016970563 | M38: =AVERAGE(E37:E38) -> 17531.5 | N38: =STDEV(E37:E38) -> 901.56115 | P38: =AVERAGE(H37:H38) -> 24.118 | Q38: =STDEV(H37:H38) -> 0.012727922 | S38: =J38-(A38-Standards!$A$121)*Standards!$AA$4 -> -3.6768176 | T38: =S38-(M38-Standards!$N$121)*Standards!$AA$55 -> -3.7101471 | W38: =P38-(A38-Standards!$A$121)*Standards!$AL$5 -> 24.035099 | X38: =W38-(M38-Standards!$N$121)*Standards!$AL$54 -> 24.114951 | Z38: =(T38*Standards!$O$156)+Standards!$O$157 -> -3.2271782 | AA38: =(X38*Standards!$T$156)+Standards!$T$157 -> 25.485706
A39: 20 | B39: A- 8A | C39: 0.218 | D39: 6 | E39: 9436 | F39: 117.428 | G39: -3.394 | H39: 24.209
A40: 20 | B40: A- 8A | C40: 0.218 | D40: 7 | E40: 8817 | F40: 109.331 | G40: -3.335 | H40: 24.219 | J40: =AVERAGE(G39:G40) -> -3.3645 | K40: =STDEV(G39:G40) -> 0.0417193 | M40: =AVERAGE(E39:E40) -> 9126.5 | N40: =STDEV(E39:E40) -> 437.6991 | P40: =AVERAGE(H39:H40) -> 24.214 | Q40: =STDEV(H39:H40) -> 0.0070710678 | S40: =J40-(A40-Standards!$A$121)*Standards!$AA$4 -> -3.4235946 | T40: =S40-(M40-Standards!$N$121)*Standards!$AA$55 -> -3.3762361 | W40: =P40-(A40-Standards!$A$121)*Standards!$AL$5 -> 24.132101 | X40: =W40-(M40-Standards!$N$121)*Standards!$AL$54 -> 24.018638 | Z40: =(T40*Standards!$O$156)+Standards!$O$157 -> -2.8911769 | AA40: =(X40*Standards!$T$156)+Standards!$T$157 -> 25.389915
A41: 21 | B41: A- 9A | C41: 0.258 | D41: 6 | E41: 13636 | F41: 162.231 | G41: -3.44 | H41: 23.989
...

Sheet 2-Full_Sorted
A1: Row | B1: Identifier 1 | C1: Identifier 2 | D1: Peak Nr | E1: Ampl 44 | F1: Area 44 | G1: d 13C/12C | H1: d 18O/16O
A3: 2 | B3: NBS18 1 | C3: 0.28 | D3: 6 | E3: 11410 | F3: 141.343 | G3: -5.456 | H3: 5.806
A4: 2 | B4: NBS18 1 | C4: 0.28 | D4: 7 | E4: 10693 | F4: 131.629 | G4: -5.421 | H4: 5.793
A5: 3 | B5: NBS18 2 | C5: 0.31 | D5: 6 | E5: 15181 | F5: 185.808 | G5: -5.448 | H5: 5.796
A6: 3 | B6: NBS18 2 | C6: 0.31 | D6: 7 | E6: 14111 | F6: 173.148 | G6: -5.407 | H6: 5.81
A7: 4 | B7: NBS18 3 | C7: 0.33 | D7: 6 | E7: 16135 | F7: 193.207 | G7: -5.387 | H7: 5.793
A8: 4 | B8: NBS18 3 | C8: 0.33 | D8: 7 | E8: 15229 | F8: 181.079 | G8: -5.304 | H8: 5.794
A9: 5 | B9: NBS18 4 | C9: 0.298 | D9: 6 | E9: 13008 | F9: 161.985 | G9: -5.437 | H9: 6.039
A10: 5 | B10: NBS18 4 | C10: 0.298 | D10: 7 | E10: 12164 | F10: 150.963 | G10: -5.4 | H10: 6.056
A11: 6 | B11: NBS19 1 | C11: 0.226 | D11: 6 | E11: 11298 | F11: 135.063 | G11: 1.441 | H11: 27.339
A12: 6 | B12: NBS19 1 | C12: 0.226 | D12: 7 | E12: 10678 | F12: 126.699 | G12: 1.503 | H12: 27.383
A13: 7 | B13: NBS19 2 | C13: 0.206 | D13: 6 | E13: 10691 | F13: 133.483 | G13: 1.48 | H13: 27.395
A14: 7 | B14: NBS19 2 | C14: 0.206 | D14: 7 | E14: 9990 | F14: 124.348 | G14: 1.55 | H14: 27.417
... A382: 198 | B382: E- 32A | C382: 0.274 | D382: 7 | E382: 10702 | F382: 124.578 | G382: -3.14 | H382: 24.333

Sheet Standards
A1: Row | B1: Line | C1: Identifier 1 | D1: Identifier 2 | E1: Peak Nr | F1: Ampl 44 | G1: Area 44 | H1: d 13C/12C | I1: d 18O/16O | K1: d 13C/12C ave | L1: stnd dev | N1: Ave Amp 44 | P1: d 18O/16O ave | Q1: stnd dev | T1: d 13C/12C drift Corr | U1: d 13C/12C amp 44 Corr | X1: d 18O/16O drift Corr | Y1: d 18O/16O amp 44 Corr
A3: 2 | B3: 2 | C3: NBS18 1 | D3: 0.28 | E3: 6 | F3: 11410 | G3: 141.343 | H3: -5.456 | I3: 5.806 | K3: =AVERAGE(H3:H4) -> -5.4385 | L3: =STDEV(H3:H4) -> 0.024748737 | N3: =AVERAGE(F3,F4) -> 11051.5 | P3: =AVERAGE(I3:I4) -> 5.7995 | Q3: =STDEV(I3:I4) -> 0.0091923882 | T3: =K3-(B3-$A$121)*$AA$4 -> -5.5106086 | U3: =T3-(N3-$N$121)*$AA$55 -> -5.4817301 | X3: =P3-(B3-$A$121)*$AL$5 -> 5.6995652 | Y3: =X3-(N3-$N$121)*$AL$54 -> 5.6303772
A4: 2 | B4: 2 | C4: NBS18 1 | D4: 0.28 | E4: 7 | F4: 10693 | G4: 131.629 | H4: -5.421 | I4: 5.793 | AA4: -0.000723 | AL4: O drift
A5: 3 | B5: 3 | C5: NBS18 2 | D5: 0.31 | E5: 6 | F5: 15181 | G5: 185.808 | H5: -5.448 | I5: 5.796 | K5: =AVERAGE(H5:H6) -> -5.4275 | L5: =STDEV(H5:H6) -> 0.028991378 | N5: =AVERAGE(F5,F6) -> 14646 | P5: =AVERAGE(I5:I6) -> 5.803 | Q5: =STDEV(I5:I6) -> 0.0098994949 | T5: =K5-(B5-$A$121)*$AA$4 -> -5.4988856 | U5: =T5-(N5-$N$121)*$AA$55 -> -5.5045143 | X5: =P5-(B5-$A$121)*$AL$5 -> 5.7040672 | Y5: =X5-(N5-$N$121)*$AL$54 -> 5.7175527 | AL5: -0.001002
A6: 3 | B6: 3 | C6: NBS18 2 | D6: 0.31 | E6: 7 | F6: 14111 | G6: 173.148 | H6: -5.407 | I6: 5.81
A7: 4 | B7: 4 | C7: NBS18 3 | D7: 0.33 | E7: 6 | F7: 16135 | G7: 193.207 | H7: -5.387 | I7: 5.793 | K7: =AVERAGE(H7:H8) -> -5.3455 | L7: =STDEV(H7:H8) -> 0.058689863 | N7: =AVERAGE(F7,F8) -> 15682 | P7: =AVERAGE(I7:I8) -> 5.7935 | Q7: =STDEV(I7:I8) -> 0.00070710678 | T7: =K7-(B7-$A$121)*$AA$4 -> -5.4161626 | U7: =T7-(N7-$N$121)*$AA$55 -> -5.4317369 | X7: =P7-(B7-$A$121)*$AL$5 -> 5.6955692 | Y7: =X7-(N7-$N$121)*$AL$54 -> 5.7328827
A8: 4 | B8: 4 | C8: NBS18 3 | D8: 0.33 | E8: 7 | F8: 15229 | G8: 181.079 | H8: -5.304 | I8: 5.794
A9: 5 | B9: 5 | C9: NBS18 4 | D9: 0.298 | E9: 6 | F9: 13008 | G9: 161.985 | H9: -5.437 | I9: 6.039 | K9: =AVERAGE(H9:H10) -> -5.4185 | L9: =STDEV(H9:H10) -> 0.026162951 | N9: =AVERAGE(F9,F10) -> 12586 | P9: =AVERAGE(I9:I10) -> 6.0475 | Q9: =STDEV(I9:I10) -> 0.012020815 | T9: =K9-(B9-$A$121)*$AA$4 -> -5.4884396 | U9: =T9-(N9-$N$121)*$AA$55 -> -5.4742923 | X9: =P9-(B9-$A$121)*$AL$5 -> 5.9505712 | Y9: =X9-(N9-$N$121)*$AL$54 -> 5.9166767
A10: 5 | B10: 5 | C10: NBS18 4 | D10: 0.298 | E10: 7 | F10: 12164 | G10: 150.963 | H10: -5.4 | I10: 6.056
A11: 103 | B11: 103 | C11: NBS18 1 | D11: 0.224 | E11: 6 | F11: 8170 | G11: 96.081 | H11: -5.613 | I11: 5.894 | K11: =AVERAGE(H11:H12) -> -5.585 | L11: =STDEV(H11:H12) -> 0.03959798 | N11: =AVERAGE(F11,F12) -> 7870.5 | P11: =AVERAGE(I11:I12) -> 5.893 | Q11: =STDEV(I11:I12) -> 0.0014142136 | T11: =K11-(B11-$A$121)*$AA$4 -> -5.5840856 | U11: =T11-(N11-$N$121)*$AA$55 -> -5.5246695 | X11: =P11-(B11-$A$121)*$AL$5 -> 5.8942672 | Y11: =X11-(N11-$N$121)*$AL$54 -> 5.7519162
A12: 103 | B12: 103 | C12: NBS18 1 | D12: 0.224 | E12: 7 | F12: 7571 | G12: 88.997 | H12: -5.557 | I12: 5.892
A13: 104 | B13: 104 | C13: NBS18 2 | D13: 0.26 | E13: 6 | F13: 13211 | G13: 148.933 | H13: -5.554 | I13: 5.625 | K13: =AVERAGE(H13:H14) -> -5.53 | L13: =STDEV(H13:H14) -> 0.033941125 | N13: =AVERAGE(F13,F14) -> 12805 | P13: =AVERAGE(I13:I14) -> 5.656 | Q13: =STDEV(I13:I14) -> 0.04384062 | T13: =K13-(B13-$A$121)*$AA$4 -> -5.5283626 | U13: =T13-(N13-$N$121)*$AA$55 -> -5.5163177 | X13: =P13-(B13-$A$121)*$AL$5 -> 5.6582692 | Y13: =X13-(N13-$N$121)*$AL$54 -> 5.6294117
A14: 104 | B14: 104 | C14: NBS18 2 | D14: 0.26 | E14: 7 | F14: 12399 | G14: 139.006 | H14: -5.506 | I14: 5.687
A15: 105 | B15: 105 | C15: NBS18 3 | D15: 0.214 | E15: 6 | F15: 9978 | G15: 117.53 | H15: -5.567 | I15: 5.82 | K15: =AVERAGE(H15:H16) -> -5.538 | L15: =STDEV(H15:H16) -> 0.041012193 | N15: =AVERAGE(F15,F16) -> 9628 | P15: =AVERAGE(I15:I16) -> 5.813 | Q15: =STDEV(I15:I16) -> 0.0098994949 | T15: =K15-(B15-$A$121)*$AA$4 -> -5.5356396 | U15: =T15-(N15-$N$121)*$AA$55 -> -5.4930955 | X15: =P15-(B15-$A$121)*$AL$5 -> 5.8162712 | Y15: =X15-(N15-$N$121)*$AL$54 -> 5.7143427
A16: 105 | B16: 105 | C16: NBS18 3 | D16: 0.214 | E16: 7 | F16: 9278 | G16: 108.882 | H16: -5.509 | I16: 5.806
A17: 106 | B17: 106 | C17: NBS18 4 | D17: 0.264 | E17: 6 | F17: 13689 | G17: 152.732 | H17: -5.534 | I17: 5.722 | K17: =AVERAGE(H17:H18) -> -5.502 | L17: =STDEV(H17:H18) -> 0.045254834 | N17: =AVERAGE(F17,F18) -> 13234.5 | P17: =AVERAGE(I17:I18) -> 5.719 | Q17: =STDEV(I17:I18) -> 0.0042426407 | T17: =K17-(B17-$A$121)*$AA$4 -> -5.4989166 | U17: =T17-(N17-$N$121)*$AA$55 -> -5.4909949 | X17: =P17-(B17-$A$121)*$AL$5 -> 5.7232732 | Y17: =X17-(N17-$N$121)*$AL$54 -> 5.7042942
A18: 106 | B18: 106 | C18: NBS18 4 | D18: 0.264 | E18: 7 | F18: 12780 | G18: 141.951 | H18: -5.47 | I18: 5.716
K21: =AVERAGE(K3:K17) -> -5.473125 | O21: Ave | P21: =AVERAGE(P3:P17) -> 5.8155625 | S21: Ave | T21: =AVERAGE(T3:T17) -> -5.5076376 | U21: =AVERAGE(U3:U17) -> -5.4896689 | W21: Ave | X21: =AVERAGE(X3:X17) -> 5.7677317 | Y21: =AVERAGE(Y3:Y17) -> 5.7246817
K22: =STDEV(K3:K17) -> 0.078690964 | O22: Std Dev | P22: =STDEV(P3:P17) -> 0.1167936 | S22: Std Dev | T22: =STDEV(T3:T17) -> 0.047742843 | U22: =STDEV(U3:U17) -> 0.028846063 | W22: Std Dev | X22: =STDEV(X3:X17) -> 0.1066794 | Y22: =STDEV(Y3:Y17) -> 0.089613562
A25: 6 | B25: 6 | C25: NBS19 1 | D25: 0.226 | E25: 6 | F25: 11298 | G25: 135.063 | H25: 1.441 | I25: 27.339 | K25: =AVERAGE(H25:H26) -> 1.472 | L25: =STDEV(H25:H26) -> 0.04384062 | N25: =AVERAGE(F25,F26) -> 10988 | P25: =AVERAGE(I25:I26) -> 27.361 | Q25: =STDEV(I25:I26) -> 0.031112698 | T25: =K25-(B25-$A$121)*$AA$4 -> 1.4027834 | U25: =T25-(N25-$N$121)*$AA$55 -> 1.4322715 | X25: =P25-(B25-$A$121)*$AL$5 -> 27.265073 | Y25: =X25-(N25-$N$121)*$AL$54 -> 27.194425
A26: 6 | B26: 6 | C26: NBS19 1 | D26: 0.226 | E26: 7 | F26: 10678 | G26: 126.699 | H26: 1.503 | I26: 27.383
A27: 7 | B27: 7 | C27: NBS19 2 | D27: 0.206 | E27: 6 | F27: 10691 | G27: 133.483 | H27: 1.48 | I27: 27.395 | K27: =AVERAGE(H27:H28) -> 1.515 | L27: =STDEV(H27:H28) -> 0.049497475 | N27: =AVERAGE(F27,F28) -> 10340.5 | P27: =AVERAGE(I27:I28) -> 27.406 | Q27: =STDEV(I27:I28) -> 0.015556349 | T27: =K27-(B27-$A$121)*$AA$4 -> 1.4465064 | U27: =T27-(N27-$N$121)*$AA$55 -> 1.4822105 | X27: =P27-(B27-$A$121)*$AL$5 -> 27.311075 | Y27: =X27-(N27-$N$121)*$AL$54 -> 27.225534
A28: 7 | B28: 7 | C28: NBS19 2 | D28: 0.206 | E28: 7 | F28: 9990 | G28: 124.348 | H28: 1.55 | I28: 27.417
A29: 8 | B29: 8 | C29: NBS19 3 | D29: 0.252 | E29: 6 | F29: 14933 | G29: 176.764 | H29: 1.485 | I29: 27.305 | K29: =AVERAGE(H29:H30) -> 1.513 | L29: =STDEV(H29:H30) -> 0.03959798 | N29: =AVERAGE(F29,F30) -> 14504.5 | P29: =AVERAGE(I29:I30) -> 27.3335 | Q29: =STDEV(I29:I30) -> 0.040305087 | T29: =K29-(B29-$A$121)*$AA$4 -> 1.4452294 | U29: =T29-(N29-$N$121)*$AA$55 -> 1.4409591 | X29: =P29-(B29-$A$121)*$AL$5 -> 27.239577 | Y29: =X29-(N29-$N$121)*$AL$54 -> 27.249808
A30: 8 | B30: 8 | C30: NBS19 3 | D30: 0.252 | E30: 7 | F30: 14076 | G30: 166.077 | H30: 1.541 | I30: 27.362
A31: 9 | B31: 9 | C31: NBS19 4 | D31: 0.28 | E31: 6 | F31: 15233 | G31: 189.197 | H31: 1.515 | I31: 27.309 | K31: =AVERAGE(H31:H32) -> 1.532 | L31: =STDEV(H31:H32) -> 0.024041631 | N31: =AVERAGE(F31,F32) -> 14717.5 | P31: =AVERAGE(I31:I32) -> 27.3155 | Q31: =STDEV(I31:I32) -> 0.0091923882 | T31: =K31-(B31-$A$121)*$AA$4 -> 1.4649524 | U31: =T31-(N31-$N$121)*$AA$55 -> 1.4586373 | X31: =P31-(B31-$A$121)*$AL$5 -> 27.222579 | Y31: =X31-(N31-$N$121)*$AL$54 -> 27.237709
A32: 9 | B32: 9 | C32: NBS19 4 | D32: 0.28 | E32: 7 | F32: 14202 | G32: 175.852 | H32: 1.549 | I32: 27.322
A33: 107 | B33: 107 | C33: NBS19 1 | D33: 0.248 | E33: 6 | F33: 10906 | G33: 127.949 | H33: 1.397 | I33: 27.174 | K33: =AVERAGE(H33:H34) -> 1.4265 | L33: =STDEV(H33:H34) -> 0.0417193 | N33: =AVERAGE(F33,F34) -> 10524 | P33: =AVERAGE(I33:I34) -> 27.2265 | Q33: =STDEV(I33:I34) -> 0.074246212 | T33: =K33-(B33-$A$121)*$AA$4 -> 1.4303064 | U33: =T33-(N33-$N$121)*$AA$55 -> 1.4642489 | X33: =P33-(B33-$A$121)*$AL$5 -> 27.231775 | Y33: =X33-(N33-$N$121)*$AL$54 -> 27.150455
A34: 107 | B34: 107 | C34: NBS19 1 | D34: 0.248 | E34: 7 | F34: 10142 | G34: 118.615 | H34: 1.456 | I34: 27.279
A35: 108 | B35: 108 | C35: NBS19 2 | D35: 0.234 | E35: 6 | F35: 12575 | G35: 140.262 | H35: 1.348 | I35: 27.201 | K35: =AVERAGE(H35:H36) -> 1.3805 | L35: =STDEV(H35:H36) -> 0.045961941 | N35: =AVERAGE(F35,F36) -> 12129 | P35: =AVERAGE(I35:I36) -> 27.233 | Q35: =STDEV(I35:I36) -> 0.045254834 | T35: =K35-(B35-$A$121)*$AA$4 -> 1.3850294 | U35: =T35-(N35-$N$121)*$AA$55 -> 1.4035639 | X35: =P35-(B35-$A$121)*$AL$5 -> 27.239277 | Y35: =X35-(N35-$N$121)*$AL$54 -> 27.194872
A36: 108 | B36: 108 | C36: NBS19 2 | D36: 0.234 | E36: 7 | F36: 11683 | G36: 130.324 | H36: 1.413 | I36: 27.265
A37: 109 | B37: 109 | C37: NBS19 3 | D37: 0.268 | E37: 6 | F37: 13910 | G37: 162.338 | H37: 1.383 | I37: 27.116 | K37: =AVERAGE(H37:H38) -> 1.4125 | L37: =STDEV(H37:H38) -> 0.0417193 | N37: =AVERAGE(F37,F38) -> 13412.5 | P37: =AVERAGE(I37:I38) -> 27.142 | Q37: =STDEV(I37:I38) -> 0.036769553 | T37: =K37-(B37-$A$121)*$AA$4 -> 1.4177524 | U37: =T37-(N37-$N$121)*$AA$55 -> 1.4239653 | X37: =P37-(B37-$A$121)*$AL$5 -> 27.149279 | Y37: =X37-(N37-$N$121)*$AL$54 -> 27.134394
A38: 109 | B38: 109 | C38: NBS19 3 | D38: 0.268 | E38: 7 | F38: 12915 | G38: 150.142 | H38: 1.442 | I38: 27.168
A39: 110 | B39: 110 | C39: NBS19 4 | D39: 0.224 | E39: 6 | F39: 12839 | G39: 144.708 | H39: 1.446 | I39: 27.229 | K39: =AVERAGE(H39:H40) -> 1.4655 | L39: =STDEV(H39:H40) -> 0.027577164 | N39: =AVERAGE(F39,F40) -> 12336.5 | P39: =AVERAGE(I39:I40) -> 27.245 | Q39: =STDEV(I39:I40) -> 0.022627417 | T39: =K39-(B39-$A$121)*$AA$4 -> 1.4714754 | U39: =T39-(N39-$N$121)*$AA$55 -> 1.4880179 | X39: =P39-(B39-$A$121)*$AL$5 -> 27.253281 | Y39: =X39-(N39-$N$121)*$AL$54 -> 27.213648
A40: 110 | B40: 110 | C40: NBS19 4 | D40: 0.224 | E40: 7 | F40: 11834 | G40: 133.883 | H40: 1.485 | I40: 27.261
K43: =AVERAGE(K25:K39) -> 1.464625 | O43: Ave | P43: =AVERAGE(P25:P39) -> 27.282812 | S43: Ave | T43: =AVERAGE(T25:T39) -> 1.4330044 | U43: =AVERAGE(U25:U39) -> 1.4492343 | W43: Ave | X43: =AVERAGE(X25:X39) -> 27.23899 | Y43: =AVERAGE(Y25:Y39) -> 27.200106
K44: =STDEV(K25:K39) -> 0.054405718 | O44: Std Dev | P44: =STDEV(P25:P39) -> 0.086053529 | S44: Std Dev | T44: =STDEV(T25:T39) -> 0.02996965 | U44: =STDEV(U25:U39) -> 0.029242765 | W44: Std Dev | X44: =STDEV(X25:X39) -> 0.045435465 | Y44: =STDEV(Y25:Y39) -> 0.040632958
A49: 10 | B49: 10 | C49: UTM 1 | D49: 0.304 | E49: 6 | F49: 17381 | G49: 204.719 | H49: 3.995 | I49: 25.23 | K49: =AVERAGE(H49:H50) -> 3.979 | L49: =STDEV(H49:H50) -> 0.022627417 | N49: =AVERAGE(F49,F50) -> 16799.5 | P49: =AVERAGE(I49:I50) -> 25.2555 | Q49: =STDEV(I49:I50) -> 0.036062446 | T49: =K49-(B49-$A$121)*$AA$4 -> 3.9126754 | U49: =T49-(N49-$N$121)*$AA$55 -> 3.8863731 | X49: =P49-(B49-$A$121)*$AL$5 -> 25.163581 | Y49: =X49-(N49-$N$121)*$AL$54 -> 25.226597
A50: 10 | B50: 10 | C50: UTM 1 | D50: 0.304 | E50: 7 | F50: 16218 | G50: 192.9 | H50: 3.963 | I50: 25.281
A51: 11 | B51: 11 | C51: UTM 2 | D51: 0.244 | E51: 6 | F51: 13560 | G51: 168.174 | H51: 3.968 | I51: 25.234 | K51: =AVERAGE(H51:H52) -> 3.9855 | L51: =STDEV(H51:H52) -> 0.024748737 | N51: =AVERAGE(F51,F52) -> 13105.5 | P51: =AVERAGE(I51:I52) -> 25.2575 | Q51: =STDEV(I51:I52) -> 0.033234019 | T51: =K51-(B51-$A$121)*$AA$4 -> 3.9198984 | U51: =T51-(N51-$N$121)*$AA$55 -> 3.9290585 | X51: =P51-(B51-$A$121)*$AL$5 -> 25.166583 | Y51: =X51-(N51-$N$121)*$AL$54 -> 25.144637
...

Sheet 1-Sorted_standards
A1: Row | B1: Row | C1: Identifier 1 | D1: Identifier 2 | E1: Peak Nr | F1: Ampl 44 | G1: Area 44 | H1: d 13C/12C | I1: d 18O/16O
A3: 2 | B3: 2 | C3: NBS18 1 | D3: 0.28 | E3: 6 | F3: 11410 | G3: 141.343 | H3: -5.456 | I3: 5.806
A4: 2 | B4: 2 | C4: NBS18 1 | D4: 0.28 | E4: 7 | F4: 10693 | G4: 131.629 | H4: -5.421 | I4: 5.793
A5: 3 | B5: 3 | C5: NBS18 2 | D5: 0.31 | E5: 6 | F5: 15181 | G5: 185.808 | H5: -5.448 | I5: 5.796
A6: 3 | B6: 3 | C6: NBS18 2 | D6: 0.31 | E6: 7 | F6: 14111 | G6: 173.148 | H6: -5.407 | I6: 5.81
A7: 4 | B7: 4 | C7: NBS18 3 | D7: 0.33 | E7: 6 | F7: 16135 | G7: 193.207 | H7: -5.387 | I7: 5.793
A8: 4 | B8: 4 | C8: NBS18 3 | D8: 0.33 | E8: 7 | F8: 15229 | G8: 181.079 | H8: -5.304 | I8: 5.794
A9: 5 | B9: 5 | C9: NBS18 4 | D9: 0.298 | E9: 6 | F9: 13008 | G9: 161.985 | H9: -5.437 | I9: 6.039
A10: 5 | B10: 5 | C10: NBS18 4 | D10: 0.298 | E10: 7 | F10: 12164 | G10: 150.963 | H10: -5.4 | I10: 6.056
A11: 6 | B11: 6 | C11: NBS19 1 | D11: 0.226 | E11: 6 | F11: 11298 | G11: 135.063 | H11: 1.441 | I11: 27.339
A12: 6 | B12: 6 | C12: NBS19 1 | D12: 0.226 | E12: 7 | F12: 10678 | G12: 126.699 | H12: 1.503 | I12: 27.383
A13: 7 | B13: 7 | C13: NBS19 2 | D13: 0.206 | E13: 6 | F13: 10691 | G13: 133.483 | H13: 1.48 | I13: 27.395
A14: 7 | B14: 7 | C14: NBS19 2 | D14: 0.206 | E14: 7 | F14: 9990 | G14: 124.348 | H14: 1.55 | I14: 27.417
... A103: 197 | B103: 197 | C103: UTM 33 | D103: 0.25 | E103: 7 | F103: 13031 | G103: 147.99 | H103: 3.945 | I103: 25.161

Sheet Raw All
A1: Row | B1: Identifier 1 | C1: Identifier 2 | D1: Comment | E1: Peak Nr | F1: Area All | G1: Ampl 44 | H1: Ampl 45 | I1: Ampl 46 | J1: Area 44 | K1: d 13C/12C | L1: d 18O/16O | M1: Information | N1: Date | O1: Time | P1: Time Code | Q1: BGD 44 | R1: BGD 45 | S1: BGD 46
A3: 1 | B3: blank | C3: 0 | D3: 1 | E3: 1 | F3: 174.237 | G3: 8894 | H3: 10642 | I3: 12314 | J3: 171.473 | K3: -5.404 | L3: 19.097 | M3: Peak Center found at (61928);Inject Sample No 1 | N3: 02/03/25 | O3: 15:55:11 | P3: 2025/02/03 15:55:11 | Q3: 9.5 | R3: 12.2 | S3: 14.4
A4: 1 | B4: blank | C4: 0 | D4: 1 | E4: 2 | F4: 172.349 | G4: 8919 | H4: 10671 | I4: 12350 | J4: 169.615 | K4: -5.404 | L4: 19.105 | M4: Peak Center found at (61928);Inject Sample No 1 | N4: 02/03/25 | O4: 15:55:11 | P4: 2025/02/03 15:55:11 | Q4: 13.6 | R4: 17.1 | S4: 20.2
A5: 1 | B5: blank | C5: 0 | D5: 1 | E5: 3 | F5: 173.707 | G5: 8978 | H5: 10742 | I5: 12430 | J5: 170.951 | K5: -5.406 | L5: 19.081 | M5: Peak Center found at (61928);Inject Sample No 1 | N5: 02/03/25 | O5: 15:55:11 | P5: 2025/02/03 15:55:11 | Q5: 14.2 | R5: 17.9 | S5: 21.1
A6: 1 | B6: blank | C6: 0 | D6: 1 | E6: 4 | F6: 173.517 | G6: 8913 | H6: 10664 | I6: 12341 | J6: 170.764 | K6: -5.399 | L6: 19.083 | M6: Peak Center found at (61928);Inject Sample No 1 | N6: 02/03/25 | O6: 15:55:11 | P6: 2025/02/03 15:55:11 | Q6: 14.5 | R6: 18.2 | S6: 21.5
A7: 2 | B7: NBS18 1 | C7: 0.28 | D7: 2 | E7: 1 | F7: 174.302 | G7: 8900 | H7: 10648 | I7: 12322 | J7: 171.537 | K7: -5.382 | L7: 19.077 | M7: Peak Center found at (61928);Inject Sample No 2 | N7: 02/03/25 | O7: 16:09:40 | P7: 2025/02/03 16:09:40 | Q7: 7.5 | R7: 9.7 | S7: 11.3
A8: 2 | B8: NBS18 1 | C8: 0.28 | D8: 2 | E8: 2 | F8: 173.182 | G8: 8948 | H8: 10706 | I8: 12390 | J8: 170.435 | K8: -5.383 | L8: 19.052 | M8: Peak Center found at (61928);Inject Sample No 2 | N8: 02/03/25 | O8: 16:09:40 | P8: 2025/02/03 16:09:40 | Q8: 12.0 | R8: 15.2 | S8: 17.8
A9: 2 | B9: NBS18 1 | C9: 0.28 | D9: 2 | E9: 3 | F9: 173.649 | G9: 8981 | H9: 10747 | I9: 12438 | J9: 170.895 | K9: -5.385 | L9: 19.054 | M9: Peak Center found at (61928);Inject Sample No 2 | N9: 02/03/25 | O9: 16:09:40 | P9: 2025/02/03 16:09:40 | Q9: 13.0 | R9: 16.3 | S9: 19.1
A10: 2 | B10: NBS18 1 | C10: 0.28 | D10: 2 | E10: 4 | F10: 174.227 | G10: 8934 | H10: 10690 | I10: 12370 | J10: 171.463 | K10: -5.399 | L10: 19.083 | M10: Peak Center found at (61928);Inject Sample No 2 | N10: 02/03/25 | O10: 16:09:40 | P10: 2025/02/03 16:09:40 | Q10: 13.5 | R10: 17.0 | S10: 19.9
A11: 2 | B11: NBS18 1 | C11: 0.28 | D11: 2 | E11: 5 | F11: 162.73 | G11: 12762 | H11: 15323 | I11: 17442 | J11: 160.158 | K11: -5.497 | L11: 5.699 | M11: Peak Center found at (61928);Inject Sample No 2 | N11: 02/03/25 | O11: 16:09:40 | P11: 2025/02/03 16:09:40 | Q11: 3.1 | R11: 4.5 | S11: 5.4
A12: 2 | B12: NBS18 1 | C12: 0.28 | D12: 2 | E12: 6 | F12: 143.613 | G12: 11410 | H12: 13696 | I12: 15595 | J12: 141.343 | K12: -5.456 | L12: 5.806 | M12: Peak Center found at (61928);Inject Sample No 2 | N12: 02/03/25 | O12: 16:09:40 | P12: 2025/02/03 16:09:40 | Q12: 15.1 | R12: 18.8 | S12: 21.6
A13: 2 | B13: NBS18 1 | C13: 0.28 | D13: 2 | E13: 7 | F13: 133.743 | G13: 10693 | H13: 12834 | I13: 14616 | J13: 131.629 | K13: -5.421 | L13: 5.793 | M13: Peak Center found at (61928);Inject Sample No 2 | N13: 02/03/25 | O13: 16:09:40 | P13: 2025/02/03 16:09:40 | Q13: 41.4 | R13: 50.2 | S13: 57.6
A14: 3 | B14: NBS18 2 | C14: 0.31 | D14: 3 | E14: 1 | F14: 174.432 | G14: 8876 | H14: 10618 | I14: 12295 | J14: 171.664 | K14: -5.391 | L14: 19.107 | M14: Peak Center found at (61919);Inject Sample No 3 | N14: 02/03/25 | O14: 16:24:10 | P14: 2025/02/03 16:24:10 | Q14: 10.4 | R14: 13.2 | S14: 15.3
... A671: 97 | B671: blank | C671: 0 | D671: 1 | E671: 4 | F671: 163.782 | G671: 8445 | H671: 10103 | I671: 11697 | J671: 161.183 | K671: -5.399 | L671: 19.083 | M671: Peak Center found at (61919);Inject Sample No 1 | N671: 02/04/25 | O671: 16:54:49 | P671: 2025/02/04 16:54:49 | Q671: 14.7 | R671: 18.4 | S671: 21.3
A672: =A664+1 -> 98 | B672: C- 8A | C672: 0.228 | D672: 93 | E672: 1 | F672: 163.787 | G672: 8365 | H672: 10008 | I672: 11588 | J672: 161.189 | K672: -5.389 | L672: 19.108 | M672: Peak Center found at (61919);Inject Sample No 93 | N672: 02/04/25 | O672: 17:09:19 | P672: 2025/02/04 17:09:19 | Q672: 7.7 | R672: 10.0 | S672: 11.3
A673: =A665+1 -> 98 | B673: C- 8A | C673: 0.228 | D673: 93 | E673: 2 | F673: 163.036 | G673: 8419 | H673: 10074 | I673: 11665 | J673: 160.449 | K673: -5.406 | L673: 19.1 | M673: Peak Center found at (61919);Inject Sample No 93 | N673: 02/04/25 | O673: 17:09:19 | P673: 2025/02/04 17:09:19 | Q673: 12.7 | R673: 16.1 | S673: 18.5
A674: =A666+1 -> 98 | B674: C- 8A | C674: 0.228 | D674: 93 | E674: 3 | F674: 163.193 | G674: 8451 | H674: 10110 | I674: 11706 | J674: 160.603 | K674: -5.413 | L674: 19.082 | M674: Peak Center found at (61919);Inject Sample No 93 | N674: 02/04/25 | O674: 17:09:19 | P674: 2025/02/04 17:09:19 | Q674: 13.8 | R674: 17.3 | S674: 20.1
A675: =A667+1 -> 98 | B675: C- 8A | C675: 0.228 | D675: 93 | E675: 4 | F675: 163.266 | G675: 8382 | H675: 10028 | I675: 11609 | J675: 160.675 | K675: -5.399 | L675: 19.083 | M675: Peak Center found at (61919);Inject Sample No 93 | N675: 02/04/25 | O675: 17:09:19 | P675: 2025/02/04 17:09:19 | Q675: 14.4 | R675: 18.0 | S675: 20.9
A676: =A668+1 -> 98 | B676: C- 8A | C676: 0.228 | D676: 93 | E676: 5 | F676: 76.028 | G676: 6316 | H676: 7595 | I676: 8795 | J676: 74.818 | K676: -2.333 | L676: 24.15 | M676: Peak Center found at (61919);Inject Sample No 93 | N676: 02/04/25 | O676: 17:09:19 | P676: 2025/02/04 17:09:19 | Q676: 3.4 | R676: 4.8 | S676: 5.4
A677: =A669+1 -> 98 | B677: C- 8A | C677: 0.228 | D677: 93 | E677: 6 | F677: 67.137 | G677: 5620 | H677: 6758 | I677: 7826 | J677: 66.068 | K677: -2.25 | L677: 24.187 | M677: Peak Center found at (61919);Inject Sample No 93 | N677: 02/04/25 | O677: 17:09:19 | P677: 2025/02/04 17:09:19 | Q677: 9.3 | R677: 11.9 | S677: 13.5
A678: =A670+1 -> 98 | B678: C- 8A | C678: 0.228 | D678: 93 | E678: 7 | F678: 62.086 | G678: 5220 | H678: 6276 | I678: 7268 | J678: 61.097 | K678: -2.224 | L678: 24.255 | M678: Peak Center found at (61919);Inject Sample No 93 | N678: 02/04/25 | O678: 17:09:19 | P678: 2025/02/04 17:09:19 | Q678: 21.9 | R678: 27.0 | S678: 31.0
A679: =A672+1 -> 99 | B679: C- 9A | C679: 0.32 | D679: 94 | E679: 1 | F679: 164.213 | G679: 8377 | H679: 10022 | I679: 11596 | J679: 161.608 | K679: -5.413 | L679: 19.066 | M679: Peak Center found at (61928);Inject Sample No 94 | N679: 02/04/25 | O679: 17:23:48 | P679: 2025/02/04 17:23:48 | Q679: 9.0 | R679: 11.6 | S679: 13.2
A680: =A673+1 -> 99 | B680: C- 9A | C680: 0.32 | D680: 94 | E680: 2 | F680: 162.565 | G680: 8408 | H680: 10059 | I680: 11639 | J680: 159.986 | K680: -5.417 | L680: 19.065 | M680: Peak Center found at (61928);Inject Sample No 94 | N680: 02/04/25 | O680: 17:23:48 | P680: 2025/02/04 17:23:48 | Q680: 13.8 | R680: 17.4 | S680: 20.0
A681: =A674+1 -> 99 | B681: C- 9A | C681: 0.32 | D681: 94 | E681: 3 | F681: 163.315 | G681: 8455 | H681: 10115 | I681: 11706 | J681: 160.724 | K681: -5.418 | L681: 19.067 | M681: Peak Center found at (61928);Inject Sample No 94 | N681: 02/04/25 | O681: 17:23:48 | P681: 2025/02/04 17:23:48 | Q681: 14.7 | R681: 18.4 | S681: 21.3
A682: =A675+1 -> 99 | B682: C- 9A | C682: 0.32 | D682: 94 | E682: 4 | F682: 164.258 | G682: 8392 | H682: 10040 | I682: 11617 | J682: 161.653 | K682: -5.399 | L682: 19.083 | M682: Peak Center found at (61928);Inject Sample No 94 | N682: 02/04/25 | O682: 17:23:48 | P682: 2025/02/04 17:23:48 | Q682: 15.1 | R682: 18.9 | S682: 22.0
A683: =A676+1 -> 99 | B683: C- 9A | C683: 0.32 | D683: 94 | E683: 5 | F683: 122.765 | G683: 10672 | H683: 12848 | I683: 14857 | J683: 120.811 | K683: -2.423 | L683: 24.239 | M683: Peak Center found at (61928);Inject Sample No 94 | N683: 02/04/25 | O683: 17:23:48 | P683: 2025/02/04 17:23:48 | Q683: 3.9 | R683: 5.5 | S683: 6.3
A684: =A677+1 -> 99 | B684: C- 9A | C684: 0.32 | D684: 94 | E684: 6 | F684: 109.454 | G684: 9479 | H684: 11407 | I684: 13195 | J684: 107.711 | K684: -2.372 | L684: 24.346 | M684: Peak Center found at (61928);Inject Sample No 94 | N684: 02/04/25 | O684: 17:23:48 | P684: 2025/02/04 17:23:48 | Q684: 12.8 | R684: 16.1 | S684: 18.4
A685: =A678+1 -> 99 | B685: C- 9A | C685: 0.32 | D685: 94 | E685: 7 | F685: 101.354 | G685: 8750 | H685: 10528 | I685: 12182 | J685: 99.74 | K685: -2.276 | L685: 24.371 | M685: Peak Center found at (61928);Inject Sample No 94 | N685: 02/04/25 | O685: 17:23:48 | P685: 2025/02/04 17:23:48 | Q685: 32.4 | R685: 39.5 | S685: 45.7
A686: =A679+1 -> 100 | B686: UTM 16 | C686: 0.31 | D686: 95 | E686: 1 | F686: 165.09 | G686: 8428 | H686: 10084 | I686: 11676 | J686: 162.471 | K686: -5.396 | L686: 19.062 | M686: Peak Center found at (61919);Inject Sample No 95 | N686: 02/04/25 | O686: 17:38:17 | P686: 2025/02/04 17:38:17 | Q686: 9.8 | R686: 12.6 | S686: 14.3
A687: =A680+1 -> 100 | B687: UTM 16 | C687: 0.31 | D687: 95 | E687: 2 | F687: 163.229 | G687: 8440 | H687: 10098 | I687: 11692 | J687: 160.639 | K687: -5.397 | L687: 19.073 | M687: Peak Center found at (61919);Inject Sample No 95 | N687: 02/04/25 | O687: 17:38:17 | P687: 2025/02/04 17:38:17 | Q687: 14.5 | R687: 18.2 | S687: 21.0
A688: =A681+1 -> 100 | B688: UTM 16 | C688: 0.31 | D688: 95 | E688: 3 | F688: 164.275 | G688: 8510 | H688: 10181 | I688: 11787 | J688: 161.668 | K688: -5.401 | L688: 19.075 | M688: Peak Center found at (61919);Inject Sample No 95 | N688: 02/04/25 | O688: 17:38:17 | P688: 2025/02/04 17:38:17 | Q688: 15.3 | R688: 19.1 | S688: 22.0
A689: =A682+1 -> 100 | B689: UTM 16 | C689: 0.31 | D689: 95 | E689: 4 | F689: 164.082 | G689: 8435 | H689: 10090 | I689: 11684 | J689: 161.479 | K689: -5.399 | L689: 19.083 | M689: Peak Center found at (61919);Inject Sample No 95 | N689: 02/04/25 | O689: 17:38:17 | P689: 2025/02/04 17:38:17 | Q689: 15.7 | R689: 19.5 | S689: 22.6
A690: =A683+1 -> 100 | B690: UTM 16 | C690: 0.31 | D690: 95 | E690: 5 | F690: 114.879 | G690: 9619 | H690: 11649 | I690: 13406 | J690: 113.042 | K690: 3.808 | L690: 25.182 | M690: Peak Center found at (61919);Inject Sample No 95 | N690: 02/04/25 | O690: 17:38:17 | P690: 2025/02/04 17:38:17 | Q690: 3.6 | R690: 5.1 | S690: 5.7
... A699: =A692+1 -> 101 | B699: UTM 17 | C699: 0.254 | D699: 96 | E699: 7 | F699: 78.562 | G699: 6594 | H699: 7977 | I699: 9189 | J699: 77.306 | K699: 4.013 | L699: 25.419 | M699: Peak Center found at (61928);Inject Sample No 96 | N699: 02/04/25 | O699: 17:52:46 | P699: 2025/02/04 17:52:46 | Q699: 26.7 | R699: 33.0 | S699: 37.8
A700: 102 | B700: blank | C700: 0 | D700: 97 | E700: 1 | F700: 163.422 | G700: 8339 | H700: 9976 | I700: 11551 | J700: 160.829 | K700: -5.4 | L700: 19.102 | M700: Peak Center found at (61919);Inject Sample No 1 | N700: 02/05/25 | O700: 12:03:00 | P700: 2025/02/05 12:03:00 | Q700: 10.5 | R700: 13.4 | S700: 15.2
A701: 102 | B701: blank | C701: 0 | D701: 97 | E701: 2 | F701: 161.058 | G701: 8315 | H701: 9946 | I701: 11517 | J701: 158.503 | K701: -5.412 | L701: 19.066 | M701: Peak Center found at (61919);Inject Sample No 1 | N701: 02/05/25 | O701: 12:03:00 | P701: 2025/02/05 12:03:00 | Q701: 15.6 | R701: 19.5 | S701: 22.4
A702: 102 | B702: blank | C702: 0 | D702: 97 | E702: 3 | F702: 162.284 | G702: 8378 | H702: 10022 | I702: 11603 | J702: 159.709 | K702: -5.421 | L702: 19.109 | M702: Peak Center found at (61919);Inject Sample No 1 | N702: 02/05/25 | O702: 12:03:00 | P702: 2025/02/05 12:03:00 | Q702: 16.4 | R702: 20.5 | S702: 23.5
A703: 102 | B703: blank | C703: 0 | D703: 97 | E703: 4 | F703: 162.026 | G703: 8319 | H703: 9952 | I703: 11522 | J703: 159.455 | K703: -5.399 | L703: 19.083 | M703: Peak Center found at (61919);Inject Sample No 1 | N703: 02/05/25 | O703: 12:03:00 | P703: 2025/02/05 12:03:00 | Q703: 16.8 | R703: 20.9 | S703: 24.0
A704: 103 | B704: NBS18 1 | C704: 0.224 | D704: 98 | E704: 1 | F704: 163.081 | G704: 8285 | H704: 9912 | I704: 11475 | J704: 160.494 | K704: -5.386 | L704: 19.092 | M704: Peak Center found at (61919);Inject Sample No 2 | N704: 02/05/25 | O704: 12:17:30 | P704: 2025/02/05 12:17:30 | Q704: 7.9 | R704: 10.3 | S704: 11.5
A705: 103 | B705: NBS18 1 | C705: 0.224 | D705: 98 | E705: 2 | F705: 160.824 | G705: 8308 | H705: 9939 | I705: 11508 | J705: 158.273 | K705: -5.397 | L705: 19.101 | M705: Peak Center found at (61919);Inject Sample No 2 | N705: 02/05/25 | O705: 12:17:30 | P705: 2025/02/05 12:17:30 | Q705: 13.6 | R705: 17.1 | S705: 19.5
...
